Workbook

Sheet pred_GDP_now
B1: GDP(SA) True | C1: DFM | D1: BEM1 | E1: BEM2 | F1: BEM3 | G1: LBVAR | H1: TFM | I1: T-M | J1: VAR | K1: SVR-KNN | L1: CRNN | M1: RF-DVS | N1: S-XGB | O1: LQR | P1: OptimARIMA | R1: Avg | S1: Med | T1: AdaMSM | U1: DQS | V1: BMA | W1: DMA | X1: LOP | Y1: AFTER | Z1: DQS_Mk2
A2: 39142 | B2: 1.8 | C2: =NA() -> #N/A | D2: 1.048504 | E2: 1.1185991 | F2: =NA() -> #N/A | G2: =NA() -> #N/A | H2: =NA() -> #N/A | I2: =NA() -> #N/A | J2: =NA() -> #N/A | K2: 1.6376398 | L2: =NA() -> #N/A | M2: 1.3805339 | N2: 1.3003066 | O2: 1.1019914 | P2: 3.1877281 | R2: 1.539329 | S2: 1.3003066 | T2: 1.539329 | U2: 1.3003066 | V2: 1.539329 | W2: 1.539329 | X2: 1.539329 | Y2: 1.539329 | Z2: 1.539329
A3: 39234 | B3: 1.7 | C3: =NA() -> #N/A | D3: 1.4101226 | E3: 1.107311 | F3: =NA() -> #N/A | G3: =NA() -> #N/A | H3: =NA() -> #N/A | I3: =NA() -> #N/A | J3: =NA() -> #N/A | K3: 1.3036866 | L3: =NA() -> #N/A | M3: 1.389925 | N3: 1.3452915 | O3: 0.74539514 | P3: 1.5231006 | R3: 1.2606904 | S3: 1.3452915 | T3: 1.2606904 | U3: 1.3452915 | V3: 1.2606904 | W3: 1.2606904 | X3: 1.2606904 | Y3: 1.2606904 | Z3: 1.2606904
A4: 39326 | B4: 1.2 | C4: =NA() -> #N/A | D4: 1.1866527 | E4: 1.1438284 | F4: =NA() -> #N/A | G4: =NA() -> #N/A | H4: =NA() -> #N/A | I4: =NA() -> #N/A | J4: =NA() -> #N/A | K4: 1.2923848 | L4: =NA() -> #N/A | M4: 1.1728845 | N4: 1.3864248 | O4: 0.9508959 | P4: 1.0981584 | R4: 1.1758899 | S4: 1.1728845 | T4: 1.1758899 | U4: 1.1728845 | V4: 1.1758899 | W4: 1.1758899 | X4: 1.1758899 | Y4: 1.1758899 | Z4: 1.1758899
A5: 39417 | B5: 2 | C5: =NA() -> #N/A | D5: 1.0176757 | E5: 0.92840886 | F5: =NA() -> #N/A | G5: =NA() -> #N/A | H5: =NA() -> #N/A | I5: =NA() -> #N/A | J5: =NA() -> #N/A | K5: 1.3413118 | L5: =NA() -> #N/A | M5: 1.0484644 | N5: 1.3644819 | O5: 2.5942174 | P5: 1.4454501 | R5: 1.39143 | S5: 1.3413118 | T5: 1.39143 | U5: 1.4167419 | V5: 1.39143 | W5: 1.39143 | X5: 1.39143 | Y5: 1.39143 | Z5: 1.39143
A6: 39508 | B6: 0.8 | C6: =NA() -> #N/A | D6: 1.1947402 | E6: 1.2456576 | F6: =NA() -> #N/A | G6: =NA() -> #N/A | H6: =NA() -> #N/A | I6: =NA() -> #N/A | J6: =NA() -> #N/A | K6: 1.0457768 | L6: =NA() -> #N/A | M6: 1.556403 | N6: 1.4444939 | O6: 1.1961049 | P6: 1.0611823 | R6: 1.2491941 | S6: 1.1961049 | T6: 1.4444939 | U6: 1.1961049 | V6: 1.1683755 | W6: 1.1744775 | X6: 1.2540484 | Y6: 1.2564375 | Z6: 1.1961049
A7: 39600 | B7: 0.4 | C7: =NA() -> #N/A | D7: 0.64868951 | E7: 0.69556962 | F7: =NA() -> #N/A | G7: =NA() -> #N/A | H7: =NA() -> #N/A | I7: =NA() -> #N/A | J7: =NA() -> #N/A | K7: 1.3910401 | L7: =NA() -> #N/A | M7: 0.82049324 | N7: 1.3672147 | O7: 1.411327 | P7: 2.4287457 | R7: 1.2518685 | S7: 1.3672147 | T7: 1.3910401 | U7: 1.4109398 | V7: 2.3039829 | W7: 2.2862086 | X7: 1.5331288 | Y7: 1.3043721 | Z7: 1.3910401
A8: 39692 | B8: 0.7 | C8: =NA() -> #N/A | D8: 1.1391836 | E8: 0.93274087 | F8: =NA() -> #N/A | G8: =NA() -> #N/A | H8: =NA() -> #N/A | I8: =NA() -> #N/A | J8: =NA() -> #N/A | K8: 1.0273119 | L8: =NA() -> #N/A | M8: 1.0254846 | N8: 1.3194889 | O8: 0.20428168 | P8: 2.1428597 | R8: 1.1130502 | S8: 1.0273119 | T8: 1.0273119 | U8: 1.0273119 | V8: 0.95521227 | W8: 0.95481296 | X8: 1.0090209 | Y8: 1.0301068 | Z8: 1.0273119
A9: 39783 | B9: -3.4 | C9: =NA() -> #N/A | D9: 1.0015324 | E9: 1.4010616 | F9: =NA() -> #N/A | G9: =NA() -> #N/A | H9: =NA() -> #N/A | I9: =NA() -> #N/A | J9: =NA() -> #N/A | K9: 0.38668635 | L9: =NA() -> #N/A | M9: 0.70541631 | N9: 1.284721 | O9: -4.5791405 | P9: -1.8814784 | R9: -0.2401716 | S9: 0.70541631 | T9: 1.0015324 | U9: -4.5791405 | V9: 0.063719427 | W9: 0.057896508 | X9: 0.014323213 | Y9: -0.037768374 | Z9: -4.5791405
A10: 39873 | B10: 0.3 | C10: =NA() -> #N/A | D10: 0.81367567 | E10: 3.5150609 | F10: =NA() -> #N/A | G10: =NA() -> #N/A | H10: =NA() -> #N/A | I10: =NA() -> #N/A | J10: =NA() -> #N/A | K10: 0.13446244 | L10: =NA() -> #N/A | M10: 0.36423815 | N10: 0.15965162 | O10: -0.3512052 | P10: 0.46065137 | R10: 0.72807641 | S10: 0.36423815 | T10: 0.13446244 | U10: 0.36423815 | V10: 0.5689414 | W10: 0.57711646 | X10: 0.21474349 | Y10: -0.1462854 | Z10: 0.36423815
A11: 39965 | B11: 1.4 | C11: =NA() -> #N/A | D11: 3.7425847 | E11: 1.8906278 | F11: =NA() -> #N/A | G11: =NA() -> #N/A | H11: =NA() -> #N/A | I11: =NA() -> #N/A | J11: =NA() -> #N/A | K11: 2.4907175 | L11: =NA() -> #N/A | M11: 1.4522385 | N11: 1.2717134 | O11: 2.3790556 | P11: 3.0218194 | R11: 2.321251 | S11: 2.3790556 | T11: 2.3790556 | U11: 2.3790556 | V11: 2.3674381 | W11: 2.365237 | X11: 2.429861 | Y11: 2.4937862 | Z11: 2.3790556
A12: 40057 | B12: 3.1 | C12: =NA() -> #N/A | D12: 3.4755381 | E12: 1.9014273 | F12: =NA() -> #N/A | G12: =NA() -> #N/A | H12: =NA() -> #N/A | I12: =NA() -> #N/A | J12: =NA() -> #N/A | K12: 1.7312036 | L12: =NA() -> #N/A | M12: 1.3394019 | N12: 1.2703278 | O12: 1.1996164 | P12: 1.7568839 | R12: 1.8106284 | S12: 1.7312036 | T12: 1.3394019 | U12: 1.7312036 | V12: 1.7548263 | W12: 1.7576416 | X12: 1.5309012 | Y12: 1.3650825 | Z12: 1.7312036
A13: 40148 | B13: 0.7 | C13: =NA() -> #N/A | D13: 3.1672886 | E13: 3.2175471 | F13: =NA() -> #N/A | G13: =NA() -> #N/A | H13: =NA() -> #N/A | I13: =NA() -> #N/A | J13: =NA() -> #N/A | K13: 1.9935973 | L13: =NA() -> #N/A | M13: 1.8420645 | N13: 1.3675604 | O13: 0.72123799 | P13: 1.4138471 | R13: 1.960449 | S13: 1.8420645 | T13: 1.4138471 | U13: 2.6829218 | V13: 1.8396348 | W13: 1.845655 | X13: 1.5394408 | Y13: 1.105101 | Z13: 1.8420645
... A37: 42339 | B37: 0.8 | C37: =NA() -> #N/A | D37: 1.4537798 | E37: 1.3268605 | F37: =NA() -> #N/A | G37: =NA() -> #N/A | H37: =NA() -> #N/A | I37: =NA() -> #N/A | J37: =NA() -> #N/A | K37: 0.80523548 | L37: =NA() -> #N/A | M37: 1.5372204 | N37: 0.75382519 | O37: 0.55163338 | P37: 0.74893733 | R37: 1.025356 | S37: 0.80523548 | T37: 0.75382519 | U37: 0.90106284 | V37: 0.96022079 | W37: 0.97029684 | X37: 1.0662204 | Y37: 1.0446593 | Z37: 0.96219713
A38: 42430 | B38: 0.3 | C38: 0.096765505 | D38: 0.199137 | E38: 0.09312 | F38: 0.225933 | G38: 0.747097 | H38: 0.47644454 | I38: 0.81979479 | J38: 0.798164 | K38: 0.35011399 | L38: -0.28277946 | M38: 0.5361807 | N38: 0.57159632 | O38: 0.303693 | P38: 0.040466 | R38: 0.29918672 | S38: 0.303693 | T38: 0.35011399 | U38: 0.303693 | V38: 0.56475536 | W38: 0.56236564 | X38: 0.36604879 | Y38: 0.30494874 | Z38: 0.30494874
A39: 42522 | B39: 1.2 | C39: 0.90968065 | D39: 0.892079 | E39: 0.84811 | F39: 0.891963 | G39: 0.351429 | H39: 1.0633698 | I39: 1.068642 | J39: 1.132944 | K39: 1.0512045 | L39: 0.5818728 | M39: 0.77269948 | N39: 1.7542191 | O39: 0.563998 | P39: 1.266576 | R39: 1.0212694 | S39: 0.892079 | T39: 1.266576 | U39: 0.94617338 | V39: 1.7504382 | W39: 1.7464551 | X39: 1.2342926 | Y39: 1.0488224 | Z39: 1.0503224
A40: 42614 | B40: 0.4 | C40: 0.55010575 | D40: 0.641954 | E40: 0.563895 | F40: 0.684774 | G40: 0.936626 | H40: 0.95351116 | I40: 0.72645207 | J40: 0.950103 | K40: 0.45401846 | L40: 0.6968781 | M40: 0.86391836 | N40: 0.92820132 | O40: 0.592652 | P40: 0.442873 | R40: 0.64107316 | S40: 0.592652 | T40: 0.45401846 | U40: 0.592652 | V40: 0.80299305 | W40: 0.78570008 | X40: 0.65525845 | Y40: 0.64263729 | Z40: 0.64107316
A41: 42705 | B41: 0.6 | C41: 1.1310326 | D41: 0.695008 | E41: 0.642045 | F41: 0.712063 | G41: 0.575754 | H41: 1.0674276 | I41: 0.87291485 | J41: 1.045621 | K41: 1.2844757 | L41: 0.96055126 | M41: 0.73464664 | N41: 1.0994868 | O41: 0.769816 | P41: 1.336816 | R41: 0.9374706 | S41: 0.769816 | T41: 1.2844757 | U41: 0.80613879 | V41: 1.2997763 | W41: 1.3000612 | X41: 1.2232967 | Y41: 0.95287776 | Z41: 1.2359258
A42: 42795 | B42: 1 | C42: 1.0771162 | D42: 1.119916 | E42: 1.097867 | F42: 1.054444 | G42: 0.647591 | H42: 1.0670232 | I42: 1.0479094 | J42: 1.113357 | K42: 1.1047905 | L42: 1.2134948 | M42: 0.81843315 | N42: 0.89296567 | O42: 1.074216 | P42: 1.447208 | R42: 1.0793423 | S42: 1.097867 | T42: 1.1047905 | U42: 1.097867 | V42: 1.1126742 | W42: 1.1121503 | X42: 1.0898468 | Y42: 1.0808498 | Z42: 1.097867
A43: 42887 | B43: 0.8 | C43: 0.50836078 | D43: 1.108525 | E43: 1.126052 | F43: 1.015314 | G43: 0.689279 | H43: 0.93246572 | I43: 0.94488392 | J43: 0.786986 | K43: 1.0296328 | L43: 0.79233724 | M43: 0.79498314 | N43: 1.1916115 | O43: 0.945407 | P43: 1.284572 | R43: 1.0686834 | S43: 1.108525 | T43: 1.108525 | U43: 1.108525 | V43: 1.1191369 | W43: 1.118753 | X43: 1.071909 | Y43: 1.0659783 | Z43: 1.108525
A44: 42979 | B44: 1.4 | C44: 0.73780532 | D44: 0.287701 | E44: 0.275753 | F44: 0.399241 | G44: 0.969641 | H44: 0.74345895 | I44: 0.8347323 | J44: 0.960132 | K44: 0.92132989 | L44: 0.6759019 | M44: 0.8004513 | N44: 0.87996209 | O44: 0.712376 | P44: 0.973802 | R44: 0.69305361 | S44: 0.8004513 | T44: 0.287701 | U44: 0.78854578 | V44: 0.55517542 | W44: 0.55052286 | X44: 0.57918316 | Y44: 0.67816135 | Z44: 0.6866258
A45: 43070 | B45: -0.3 | C45: 0.71009689 | D45: 0.952379 | E45: 0.673771 | F45: 0.895778 | G45: 1.387553 | H45: 0.8721196 | I45: 0.89416043 | J45: 0.694095 | K45: 0.51212529 | L45: 0.71935225 | M45: 0.74325214 | N45: 0.79880202 | O45: 0.354928 | P45: 0.478414 | R45: 0.64481021 | S45: 0.673771 | T45: 0.51212529 | U45: 0.673771 | V45: 0.67328624 | W45: 0.66885828 | X45: 0.62847002 | Y45: 0.63947285 | Z45: 0.66885828
A46: 43160 | B46: 1.3 | C46: 1.1079978 | D46: 0.678722 | E46: 0.808093 | F46: 0.709687 | G46: 0.753485 | H46: 0.9775264 | I46: 1.005438 | J46: 0.937068 | K46: 1.2140902 | L46: 0.80441034 | M46: 1.1117773 | N46: 0.71219826 | O46: 0.744322 | P46: 1.71661 | R46: 0.99797324 | S46: 0.808093 | T46: 1.1117773 | U46: 0.89751485 | V46: 1.0717308 | W46: 1.0751327 | X46: 1.0486376 | Y46: 1.0250389 | Z46: 1.0344488
A47: 43252 | B47: 0.7 | C47: 0.95959584 | D47: 0.711343 | E47: 0.552336 | F47: 0.701288 | G47: 0.31626 | H47: 0.56679147 | I47: 0.54893017 | J47: 0.837201 | K47: 0.57726227 | L47: 0.6337409 | M47: 0.4999584 | N47: 1.3132168 | O47: 0.687899 | P47: 0.596387 | R47: 0.70548607 | S47: 0.596387 | T47: 0.57726227 | U47: 0.596387 | V47: 0.61496505 | W47: 0.61727076 | X47: 0.67712818 | Y47: 0.69572678 | Z47: 0.61496505
A48: 43344 | B48: 0.6 | C48: 0.97109739 | D48: 0.523688 | E48: 0.475666 | F48: 0.571424 | G48: 0.361778 | H48: 1.0800163 | I48: 1.0457688 | J48: 0.701816 | K48: 0.60425636 | L48: 0.34749293 | M48: 0.5807563 | N48: 0.68545735 | O48: 0.679213 | P48: 0.320519 | R48: 0.55279372 | S48: 0.5807563 | T48: 0.60425636 | U48: 0.5807563 | V48: 0.52081456 | W48: 0.52213095 | X48: 0.54449227 | Y48: 0.55131258 | Z48: 0.55279372
A49: 43435 | B49: 0.6 | C49: 0.26589153 | D49: 0.09694 | E49: -0.02169 | F49: 0.245889 | G49: 0.749574 | H49: 0.35103274 | I49: 0.66124605 | J49: 0.703083 | K49: 0.45311828 | L49: 0.056084156 | M49: 1.1399713 | N49: 0.7254836 | O49: 0.117679 | P49: 0.410747 | R49: 0.41746417 | S49: 0.410747 | T49: 0.45311828 | U49: 0.24523067 | V49: 0.34390361 | W49: 0.34514599 | X49: 0.40246786 | Y49: 0.41480533 | Z49: 0.40927768
... A65: 44896 | B65: -0.3 | C65: -0.80932658 | D65: -0.78486 | E65: -0.93253 | F65: -0.55036 | G65: -0.03764 | H65: 0.004307387 | I65: 0.45885565 | J65: -0.43845 | K65: 0.045649434 | L65: -0.58131605 | M65: 0.15493006 | N65: 0.28175333 | O65: -0.714974 | P65: -0.435121 | R65: -0.34073602 | S65: -0.435121 | T65: -0.78486 | U65: -0.63194467 | V65: -0.86153551 | W65: -0.81073761 | X65: -0.46786763 | Y65: -0.35269366 | Z65: -0.48237347
C66: .

Sheet error_now
B1: GDP(SA) True | C1: DFM | D1: BEM1 | E1: BEM2 | F1: BEM3 | G1: LBVAR | H1: TFM | I1: T-M | J1: VAR | K1: SVR-KNN | L1: CRNN | M1: RF-DVS | N1: S-XGB | O1: LQR | P1: OptimARIMA | R1: Avg | S1: Med | T1: AdaMSM | U1: DQS | V1: BMA | W1: DMA | X1: LOP | Y1: AFTER | Z1: DQS_Mk2
A2: 39508 | B2: 0.8 | C2: {=ABS(pred_GDP_now!C6-pred_GDP_now!$B6)} -> #N/A | D2: {=ABS(pred_GDP_now!D6-pred_GDP_now!$B6)} -> 0.3947402 | E2: {=ABS(pred_GDP_now!E6-pred_GDP_now!$B6)} -> 0.44565759 | F2: {=ABS(pred_GDP_now!F6-pred_GDP_now!$B6)} -> #N/A | G2: {=ABS(pred_GDP_now!G6-pred_GDP_now!$B6)} -> #N/A | H2: {=ABS(pred_GDP_now!H6-pred_GDP_now!$B6)} -> #N/A | I2: {=ABS(pred_GDP_now!I6-pred_GDP_now!$B6)} -> #N/A | J2: {=ABS(pred_GDP_now!J6-pred_GDP_now!$B6)} -> #N/A | ... P2: {=ABS(pred_GDP_now!P6-pred_GDP_now!$B6)} -> 0.26118233 | R2: {=ABS(pred_GDP_now!R6-pred_GDP_now!$B6)} -> 0.44919411 | S2: {=ABS(pred_GDP_now!S6-pred_GDP_now!$B6)} -> 0.39610491 | T2: {=ABS(pred_GDP_now!T6-pred_GDP_now!$B6)} -> 0.64449389 | U2: {=ABS(pred_GDP_now!U6-pred_GDP_now!$B6)} -> 0.39610491 | V2: {=ABS(pred_GDP_now!V6-pred_GDP_now!$B6)} -> 0.36837552 | W2: {=ABS(pred_GDP_now!W6-pred_GDP_now!$B6)} -> 0.37447745 | X2: {=ABS(pred_GDP_now!X6-pred_GDP_now!$B6)} -> 0.45404842 | Y2: {=ABS(pred_GDP_now!Y6-pred_GDP_now!$B6)} -> 0.45643749 | Z2: {=ABS(pred_GDP_now!Z6-pred_GDP_now!$B6)} -> 0.39610491
A3: 39600 | B3: 0.4 | C3: {=ABS(pred_GDP_now!C7-pred_GDP_now!$B7)} -> #N/A | D3: {=ABS(pred_GDP_now!D7-pred_GDP_now!$B7)} -> 0.24868951 | E3: {=ABS(pred_GDP_now!E7-pred_GDP_now!$B7)} -> 0.29556962 | F3: {=ABS(pred_GDP_now!F7-pred_GDP_now!$B7)} -> #N/A | G3: {=ABS(pred_GDP_now!G7-pred_GDP_now!$B7)} -> #N/A | H3: {=ABS(pred_GDP_now!H7-pred_GDP_now!$B7)} -> #N/A | I3: {=ABS(pred_GDP_now!I7-pred_GDP_now!$B7)} -> #N/A | J3: {=ABS(pred_GDP_now!J7-pred_GDP_now!$B7)} -> #N/A | ... P3: {=ABS(pred_GDP_now!P7-pred_GDP_now!$B7)} -> 2.0287457 | R3: {=ABS(pred_GDP_now!R7-pred_GDP_now!$B7)} -> 0.85186855 | S3: {=ABS(pred_GDP_now!S7-pred_GDP_now!$B7)} -> 0.96721468 | T3: {=ABS(pred_GDP_now!T7-pred_GDP_now!$B7)} -> 0.99104008 | U3: {=ABS(pred_GDP_now!U7-pred_GDP_now!$B7)} -> 1.0109398 | V3: {=ABS(pred_GDP_now!V7-pred_GDP_now!$B7)} -> 1.9039829 | W3: {=ABS(pred_GDP_now!W7-pred_GDP_now!$B7)} -> 1.8862086 | X3: {=ABS(pred_GDP_now!X7-pred_GDP_now!$B7)} -> 1.1331288 | Y3: {=ABS(pred_GDP_now!Y7-pred_GDP_now!$B7)} -> 0.90437209 | Z3: {=ABS(pred_GDP_now!Z7-pred_GDP_now!$B7)} -> 0.99104008
A4: 39692 | B4: 0.7 | C4: {=ABS(pred_GDP_now!C8-pred_GDP_now!$B8)} -> #N/A | D4: {=ABS(pred_GDP_now!D8-pred_GDP_now!$B8)} -> 0.43918357 | E4: {=ABS(pred_GDP_now!E8-pred_GDP_now!$B8)} -> 0.23274087 | F4: {=ABS(pred_GDP_now!F8-pred_GDP_now!$B8)} -> #N/A | G4: {=ABS(pred_GDP_now!G8-pred_GDP_now!$B8)} -> #N/A | H4: {=ABS(pred_GDP_now!H8-pred_GDP_now!$B8)} -> #N/A | I4: {=ABS(pred_GDP_now!I8-pred_GDP_now!$B8)} -> #N/A | J4: {=ABS(pred_GDP_now!J8-pred_GDP_now!$B8)} -> #N/A | ... P4: {=ABS(pred_GDP_now!P8-pred_GDP_now!$B8)} -> 1.4428597 | R4: {=ABS(pred_GDP_now!R8-pred_GDP_now!$B8)} -> 0.41305016 | S4: {=ABS(pred_GDP_now!S8-pred_GDP_now!$B8)} -> 0.32731186 | T4: {=ABS(pred_GDP_now!T8-pred_GDP_now!$B8)} -> 0.32731186 | U4: {=ABS(pred_GDP_now!U8-pred_GDP_now!$B8)} -> 0.32731186 | V4: {=ABS(pred_GDP_now!V8-pred_GDP_now!$B8)} -> 0.25521227 | W4: {=ABS(pred_GDP_now!W8-pred_GDP_now!$B8)} -> 0.25481296 | X4: {=ABS(pred_GDP_now!X8-pred_GDP_now!$B8)} -> 0.30902091 | Y4: {=ABS(pred_GDP_now!Y8-pred_GDP_now!$B8)} -> 0.33010683 | Z4: {=ABS(pred_GDP_now!Z8-pred_GDP_now!$B8)} -> 0.32731186
A5: 39783 | B5: -3.4 | C5: {=ABS(pred_GDP_now!C9-pred_GDP_now!$B9)} -> #N/A | D5: {=ABS(pred_GDP_now!D9-pred_GDP_now!$B9)} -> 4.4015324 | E5: {=ABS(pred_GDP_now!E9-pred_GDP_now!$B9)} -> 4.8010616 | F5: {=ABS(pred_GDP_now!F9-pred_GDP_now!$B9)} -> #N/A | G5: {=ABS(pred_GDP_now!G9-pred_GDP_now!$B9)} -> #N/A | H5: {=ABS(pred_GDP_now!H9-pred_GDP_now!$B9)} -> #N/A | I5: {=ABS(pred_GDP_now!I9-pred_GDP_now!$B9)} -> #N/A | J5: {=ABS(pred_GDP_now!J9-pred_GDP_now!$B9)} -> #N/A | ... P5: {=ABS(pred_GDP_now!P9-pred_GDP_now!$B9)} -> 1.5185216 | R5: {=ABS(pred_GDP_now!R9-pred_GDP_now!$B9)} -> 3.1598284 | S5: {=ABS(pred_GDP_now!S9-pred_GDP_now!$B9)} -> 4.1054163 | T5: {=ABS(pred_GDP_now!T9-pred_GDP_now!$B9)} -> 4.4015324 | U5: {=ABS(pred_GDP_now!U9-pred_GDP_now!$B9)} -> 1.1791405 | V5: {=ABS(pred_GDP_now!V9-pred_GDP_now!$B9)} -> 3.4637194 | W5: {=ABS(pred_GDP_now!W9-pred_GDP_now!$B9)} -> 3.4578965 | X5: {=ABS(pred_GDP_now!X9-pred_GDP_now!$B9)} -> 3.4143232 | Y5: {=ABS(pred_GDP_now!Y9-pred_GDP_now!$B9)} -> 3.3622316 | Z5: {=ABS(pred_GDP_now!Z9-pred_GDP_now!$B9)} -> 1.1791405
A6: 39873 | B6: 0.3 | C6: {=ABS(pred_GDP_now!C10-pred_GDP_now!$B10)} -> #N/A | D6: {=ABS(pred_GDP_now!D10-pred_GDP_now!$B10)} -> 0.51367567 | E6: {=ABS(pred_GDP_now!E10-pred_GDP_now!$B10)} -> 3.2150609 | F6: {=ABS(pred_GDP_now!F10-pred_GDP_now!$B10)} -> #N/A | G6: {=ABS(pred_GDP_now!G10-pred_GDP_now!$B10)} -> #N/A | H6: {=ABS(pred_GDP_now!H10-pred_GDP_now!$B10)} -> #N/A | I6: {=ABS(pred_GDP_now!I10-pred_GDP_now!$B10)} -> #N/A | J6: {=ABS(pred_GDP_now!J10-pred_GDP_now!$B10)} -> #N/A | ... P6: {=ABS(pred_GDP_now!P10-pred_GDP_now!$B10)} -> 0.16065137 | R6: {=ABS(pred_GDP_now!R10-pred_GDP_now!$B10)} -> 0.42807641 | S6: {=ABS(pred_GDP_now!S10-pred_GDP_now!$B10)} -> 0.064238147 | T6: {=ABS(pred_GDP_now!T10-pred_GDP_now!$B10)} -> 0.16553756 | U6: {=ABS(pred_GDP_now!U10-pred_GDP_now!$B10)} -> 0.064238147 | V6: {=ABS(pred_GDP_now!V10-pred_GDP_now!$B10)} -> 0.2689414 | W6: {=ABS(pred_GDP_now!W10-pred_GDP_now!$B10)} -> 0.27711646 | X6: {=ABS(pred_GDP_now!X10-pred_GDP_now!$B10)} -> 0.085256508 | Y6: {=ABS(pred_GDP_now!Y10-pred_GDP_now!$B10)} -> 0.4462854 | Z6: {=ABS(pred_GDP_now!Z10-pred_GDP_now!$B10)} -> 0.064238147
A7: 39965 | B7: 1.4 | C7: {=ABS(pred_GDP_now!C11-pred_GDP_now!$B11)} -> #N/A | D7: {=ABS(pred_GDP_now!D11-pred_GDP_now!$B11)} -> 2.3425847 | E7: {=ABS(pred_GDP_now!E11-pred_GDP_now!$B11)} -> 0.49062785 | F7: {=ABS(pred_GDP_now!F11-pred_GDP_now!$B11)} -> #N/A | G7: {=ABS(pred_GDP_now!G11-pred_GDP_now!$B11)} -> #N/A | H7: {=ABS(pred_GDP_now!H11-pred_GDP_now!$B11)} -> #N/A | I7: {=ABS(pred_GDP_now!I11-pred_GDP_now!$B11)} -> #N/A | J7: {=ABS(pred_GDP_now!J11-pred_GDP_now!$B11)} -> #N/A | ... P7: {=ABS(pred_GDP_now!P11-pred_GDP_now!$B11)} -> 1.6218194 | R7: {=ABS(pred_GDP_now!R11-pred_GDP_now!$B11)} -> 0.92125097 | S7: {=ABS(pred_GDP_now!S11-pred_GDP_now!$B11)} -> 0.97905557 | T7: {=ABS(pred_GDP_now!T11-pred_GDP_now!$B11)} -> 0.97905557 | U7: {=ABS(pred_GDP_now!U11-pred_GDP_now!$B11)} -> 0.97905557 | V7: {=ABS(pred_GDP_now!V11-pred_GDP_now!$B11)} -> 0.96743807 | W7: {=ABS(pred_GDP_now!W11-pred_GDP_now!$B11)} -> 0.96523701 | X7: {=ABS(pred_GDP_now!X11-pred_GDP_now!$B11)} -> 1.029861 | Y7: {=ABS(pred_GDP_now!Y11-pred_GDP_now!$B11)} -> 1.0937862 | Z7: {=ABS(pred_GDP_now!Z11-pred_GDP_now!$B11)} -> 0.97905557
A8: 40057 | B8: 3.1 | C8: {=ABS(pred_GDP_now!C12-pred_GDP_now!$B12)} -> #N/A | D8: {=ABS(pred_GDP_now!D12-pred_GDP_now!$B12)} -> 0.37553811 | E8: {=ABS(pred_GDP_now!E12-pred_GDP_now!$B12)} -> 1.1985727 | F8: {=ABS(pred_GDP_now!F12-pred_GDP_now!$B12)} -> #N/A | G8: {=ABS(pred_GDP_now!G12-pred_GDP_now!$B12)} -> #N/A | H8: {=ABS(pred_GDP_now!H12-pred_GDP_now!$B12)} -> #N/A | I8: {=ABS(pred_GDP_now!I12-pred_GDP_now!$B12)} -> #N/A | J8: {=ABS(pred_GDP_now!J12-pred_GDP_now!$B12)} -> #N/A | ... P8: {=ABS(pred_GDP_now!P12-pred_GDP_now!$B12)} -> 1.3431161 | R8: {=ABS(pred_GDP_now!R12-pred_GDP_now!$B12)} -> 1.2893716 | S8: {=ABS(pred_GDP_now!S12-pred_GDP_now!$B12)} -> 1.3687964 | T8: {=ABS(pred_GDP_now!T12-pred_GDP_now!$B12)} -> 1.7605981 | U8: {=ABS(pred_GDP_now!U12-pred_GDP_now!$B12)} -> 1.3687964 | V8: {=ABS(pred_GDP_now!V12-pred_GDP_now!$B12)} -> 1.3451737 | W8: {=ABS(pred_GDP_now!W12-pred_GDP_now!$B12)} -> 1.3423584 | X8: {=ABS(pred_GDP_now!X12-pred_GDP_now!$B12)} -> 1.5690988 | Y8: {=ABS(pred_GDP_now!Y12-pred_GDP_now!$B12)} -> 1.7349175 | Z8: {=ABS(pred_GDP_now!Z12-pred_GDP_now!$B12)} -> 1.3687964
A9: 40148 | B9: 0.7 | C9: {=ABS(pred_GDP_now!C13-pred_GDP_now!$B13)} -> #N/A | D9: {=ABS(pred_GDP_now!D13-pred_GDP_now!$B13)} -> 2.4672886 | E9: {=ABS(pred_GDP_now!E13-pred_GDP_now!$B13)} -> 2.5175471 | F9: {=ABS(pred_GDP_now!F13-pred_GDP_now!$B13)} -> #N/A | G9: {=ABS(pred_GDP_now!G13-pred_GDP_now!$B13)} -> #N/A | H9: {=ABS(pred_GDP_now!H13-pred_GDP_now!$B13)} -> #N/A | I9: {=ABS(pred_GDP_now!I13-pred_GDP_now!$B13)} -> #N/A | J9: {=ABS(pred_GDP_now!J13-pred_GDP_now!$B13)} -> #N/A | ... P9: {=ABS(pred_GDP_now!P13-pred_GDP_now!$B13)} -> 0.71384705 | R9: {=ABS(pred_GDP_now!R13-pred_GDP_now!$B13)} -> 1.260449 | S9: {=ABS(pred_GDP_now!S13-pred_GDP_now!$B13)} -> 1.1420645 | T9: {=ABS(pred_GDP_now!T13-pred_GDP_now!$B13)} -> 0.71384705 | U9: {=ABS(pred_GDP_now!U13-pred_GDP_now!$B13)} -> 1.9829218 | V9: {=ABS(pred_GDP_now!V13-pred_GDP_now!$B13)} -> 1.1396348 | W9: {=ABS(pred_GDP_now!W13-pred_GDP_now!$B13)} -> 1.145655 | X9: {=ABS(pred_GDP_now!X13-pred_GDP_now!$B13)} -> 0.83944085 | Y9: {=ABS(pred_GDP_now!Y13-pred_GDP_now!$B13)} -> 0.40510095 | Z9: {=ABS(pred_GDP_now!Z13-pred_GDP_now!$B13)} -> 1.1420645
A10: 40238 | B10: 2.3 | C10: {=ABS(pred_GDP_now!C14-pred_GDP_now!$B14)} -> #N/A | D10: {=ABS(pred_GDP_now!D14-pred_GDP_now!$B14)} -> 0.058816128 | E10: {=ABS(pred_GDP_now!E14-pred_GDP_now!$B14)} -> 0.80071575 | F10: {=ABS(pred_GDP_now!F14-pred_GDP_now!$B14)} -> #N/A | G10: {=ABS(pred_GDP_now!G14-pred_GDP_now!$B14)} -> #N/A | H10: {=ABS(pred_GDP_now!H14-pred_GDP_now!$B14)} -> #N/A | I10: {=ABS(pred_GDP_now!I14-pred_GDP_now!$B14)} -> #N/A | J10: {=ABS(pred_GDP_now!J14-pred_GDP_now!$B14)} -> #N/A | ... P10: {=ABS(pred_GDP_now!P14-pred_GDP_now!$B14)} -> 0.24707694 | R10: {=ABS(pred_GDP_now!R14-pred_GDP_now!$B14)} -> 0.76109325 | S10: {=ABS(pred_GDP_now!S14-pred_GDP_now!$B14)} -> 0.80071575 | T10: {=ABS(pred_GDP_now!T14-pred_GDP_now!$B14)} -> 1.0699218 | U10: {=ABS(pred_GDP_now!U14-pred_GDP_now!$B14)} -> 0.80071575 | V10: {=ABS(pred_GDP_now!V14-pred_GDP_now!$B14)} -> 0.81034211 | W10: {=ABS(pred_GDP_now!W14-pred_GDP_now!$B14)} -> 0.80809075 | X10: {=ABS(pred_GDP_now!X14-pred_GDP_now!$B14)} -> 0.8477862 | Y10: {=ABS(pred_GDP_now!Y14-pred_GDP_now!$B14)} -> 0.88870647 | Z10: {=ABS(pred_GDP_now!Z14-pred_GDP_now!$B14)} -> 0.80809075
A11: 40330 | B11: 1.6 | C11: {=ABS(pred_GDP_now!C15-pred_GDP_now!$B15)} -> #N/A | D11: {=ABS(pred_GDP_now!D15-pred_GDP_now!$B15)} -> 0.53295288 | E11: {=ABS(pred_GDP_now!E15-pred_GDP_now!$B15)} -> 0.10690076 | F11: {=ABS(pred_GDP_now!F15-pred_GDP_now!$B15)} -> #N/A | G11: {=ABS(pred_GDP_now!G15-pred_GDP_now!$B15)} -> #N/A | H11: {=ABS(pred_GDP_now!H15-pred_GDP_now!$B15)} -> #N/A | I11: {=ABS(pred_GDP_now!I15-pred_GDP_now!$B15)} -> #N/A | J11: {=ABS(pred_GDP_now!J15-pred_GDP_now!$B15)} -> #N/A | ... P11: {=ABS(pred_GDP_now!P15-pred_GDP_now!$B15)} -> 0.57221209 | R11: {=ABS(pred_GDP_now!R15-pred_GDP_now!$B15)} -> 0.11556715 | S11: {=ABS(pred_GDP_now!S15-pred_GDP_now!$B15)} -> 0.10690076 | T11: {=ABS(pred_GDP_now!T15-pred_GDP_now!$B15)} -> 0.20529244 | U11: {=ABS(pred_GDP_now!U15-pred_GDP_now!$B15)} -> 0.10690076 | V11: {=ABS(pred_GDP_now!V15-pred_GDP_now!$B15)} -> 0.0060670746 | W11: {=ABS(pred_GDP_now!W15-pred_GDP_now!$B15)} -> 0.0017179878 | X11: {=ABS(pred_GDP_now!X15-pred_GDP_now!$B15)} -> 0.046440816 | Y11: {=ABS(pred_GDP_now!Y15-pred_GDP_now!$B15)} -> 0.0078699769 | Z11: {=ABS(pred_GDP_now!Z15-pred_GDP_now!$B15)} -> 0.046440816
A12: 40422 | B12: 1 | C12: {=ABS(pred_GDP_now!C16-pred_GDP_now!$B16)} -> #N/A | D12: {=ABS(pred_GDP_now!D16-pred_GDP_now!$B16)} -> 0.32042766 | E12: {=ABS(pred_GDP_now!E16-pred_GDP_now!$B16)} -> 0.31834018 | F12: {=ABS(pred_GDP_now!F16-pred_GDP_now!$B16)} -> #N/A | G12: {=ABS(pred_GDP_now!G16-pred_GDP_now!$B16)} -> #N/A | H12: {=ABS(pred_GDP_now!H16-pred_GDP_now!$B16)} -> #N/A | I12: {=ABS(pred_GDP_now!I16-pred_GDP_now!$B16)} -> #N/A | J12: {=ABS(pred_GDP_now!J16-pred_GDP_now!$B16)} -> #N/A | ... P12: {=ABS(pred_GDP_now!P16-pred_GDP_now!$B16)} -> 0.50778058 | R12: {=ABS(pred_GDP_now!R16-pred_GDP_now!$B16)} -> 0.15244079 | S12: {=ABS(pred_GDP_now!S16-pred_GDP_now!$B16)} -> 0.32042766 | T12: {=ABS(pred_GDP_now!T16-pred_GDP_now!$B16)} -> 0.32042766 | U12: {=ABS(pred_GDP_now!U16-pred_GDP_now!$B16)} -> 0.32002411 | V12: {=ABS(pred_GDP_now!V16-pred_GDP_now!$B16)} -> 0.019879599 | W12: {=ABS(pred_GDP_now!W16-pred_GDP_now!$B16)} -> 0.030499068 | X12: {=ABS(pred_GDP_now!X16-pred_GDP_now!$B16)} -> 0.10333728 | Y12: {=ABS(pred_GDP_now!Y16-pred_GDP_now!$B16)} -> 0.11467186 | Z12: {=ABS(pred_GDP_now!Z16-pred_GDP_now!$B16)} -> 0.2960291
A13: 40513 | B13: 1.4 | C13: {=ABS(pred_GDP_now!C17-pred_GDP_now!$B17)} -> #N/A | D13: {=ABS(pred_GDP_now!D17-pred_GDP_now!$B17)} -> 0.14552127 | E13: {=ABS(pred_GDP_now!E17-pred_GDP_now!$B17)} -> 0.069304818 | F13: {=ABS(pred_GDP_now!F17-pred_GDP_now!$B17)} -> #N/A | G13: {=ABS(pred_GDP_now!G17-pred_GDP_now!$B17)} -> #N/A | H13: {=ABS(pred_GDP_now!H17-pred_GDP_now!$B17)} -> #N/A | I13: {=ABS(pred_GDP_now!I17-pred_GDP_now!$B17)} -> #N/A | J13: {=ABS(pred_GDP_now!J17-pred_GDP_now!$B17)} -> #N/A | ... P13: {=ABS(pred_GDP_now!P17-pred_GDP_now!$B17)} -> 0.21557035 | R13: {=ABS(pred_GDP_now!R17-pred_GDP_now!$B17)} -> 0.066456543 | S13: {=ABS(pred_GDP_now!S17-pred_GDP_now!$B17)} -> 0.075687842 | T13: {=ABS(pred_GDP_now!T17-pred_GDP_now!$B17)} -> 0.1441864 | U13: {=ABS(pred_GDP_now!U17-pred_GDP_now!$B17)} -> 0.075687842 | V13: {=ABS(pred_GDP_now!V17-pred_GDP_now!$B17)} -> 0.085706972 | W13: {=ABS(pred_GDP_now!W17-pred_GDP_now!$B17)} -> 0.084332224 | X13: {=ABS(pred_GDP_now!X17-pred_GDP_now!$B17)} -> 0.094764327 | Y13: {=ABS(pred_GDP_now!Y17-pred_GDP_now!$B17)} -> 0.076683884 | Z13: {=ABS(pred_GDP_now!Z17-pred_GDP_now!$B17)} -> 0.076683884
... A32: 42248 | B32: 1.5 | C32: {=ABS(pred_GDP_now!C36-pred_GDP_now!$B36)} -> #N/A | D32: {=ABS(pred_GDP_now!D36-pred_GDP_now!$B36)} -> 0.32594066 | E32: {=ABS(pred_GDP_now!E36-pred_GDP_now!$B36)} -> 0.33186561 | F32: {=ABS(pred_GDP_now!F36-pred_GDP_now!$B36)} -> #N/A | G32: {=ABS(pred_GDP_now!G36-pred_GDP_now!$B36)} -> #N/A | H32: {=ABS(pred_GDP_now!H36-pred_GDP_now!$B36)} -> #N/A | I32: {=ABS(pred_GDP_now!I36-pred_GDP_now!$B36)} -> #N/A | J32: {=ABS(pred_GDP_now!J36-pred_GDP_now!$B36)} -> #N/A | ... P32: {=ABS(pred_GDP_now!P36-pred_GDP_now!$B36)} -> 0.93324635 | R32: {=ABS(pred_GDP_now!R36-pred_GDP_now!$B36)} -> 0.61802872 | S32: {=ABS(pred_GDP_now!S36-pred_GDP_now!$B36)} -> 0.57917786 | T32: {=ABS(pred_GDP_now!T36-pred_GDP_now!$B36)} -> 0.81117948 | U32: {=ABS(pred_GDP_now!U36-pred_GDP_now!$B36)} -> 0.57917786 | V32: {=ABS(pred_GDP_now!V36-pred_GDP_now!$B36)} -> 0.80167943 | W32: {=ABS(pred_GDP_now!W36-pred_GDP_now!$B36)} -> 0.79642506 | X32: {=ABS(pred_GDP_now!X36-pred_GDP_now!$B36)} -> 0.70945674 | Y32: {=ABS(pred_GDP_now!Y36-pred_GDP_now!$B36)} -> 0.63649334 | Z32: {=ABS(pred_GDP_now!Z36-pred_GDP_now!$B36)} -> 0.63195567
A33: 42339 | B33: 0.8 | C33: {=ABS(pred_GDP_now!C37-pred_GDP_now!$B37)} -> #N/A | D33: {=ABS(pred_GDP_now!D37-pred_GDP_now!$B37)} -> 0.6537798 | E33: {=ABS(pred_GDP_now!E37-pred_GDP_now!$B37)} -> 0.52686048 | F33: {=ABS(pred_GDP_now!F37-pred_GDP_now!$B37)} -> #N/A | G33: {=ABS(pred_GDP_now!G37-pred_GDP_now!$B37)} -> #N/A | H33: {=ABS(pred_GDP_now!H37-pred_GDP_now!$B37)} -> #N/A | I33: {=ABS(pred_GDP_now!I37-pred_GDP_now!$B37)} -> #N/A | J33: {=ABS(pred_GDP_now!J37-pred_GDP_now!$B37)} -> #N/A | ... P33: {=ABS(pred_GDP_now!P37-pred_GDP_now!$B37)} -> 0.051062665 | R33: 0.025279185 | S33: 0.003693 | T33: 0.025279185 | U33: 0.003693 | V33: 0.025279185 | W33: 0.025279185 | X33: 0.025279185 | Y33: 0.025279185 | Z33: 0.025279185
A34: 42430 | B34: 0.3 | C34: {=ABS(pred_GDP_now!C38-pred_GDP_now!$B38)} -> 0.20323449 | D34: {=ABS(pred_GDP_now!D38-pred_GDP_now!$B38)} -> 0.100863 | E34: {=ABS(pred_GDP_now!E38-pred_GDP_now!$B38)} -> 0.20688 | F34: {=ABS(pred_GDP_now!F38-pred_GDP_now!$B38)} -> 0.074067 | G34: {=ABS(pred_GDP_now!G38-pred_GDP_now!$B38)} -> 0.447097 | H34: {=ABS(pred_GDP_now!H38-pred_GDP_now!$B38)} -> 0.17644454 | I34: {=ABS(pred_GDP_now!I38-pred_GDP_now!$B38)} -> 0.51979479 | J34: {=ABS(pred_GDP_now!J38-pred_GDP_now!$B38)} -> 0.498164 | ... P34: {=ABS(pred_GDP_now!P38-pred_GDP_now!$B38)} -> 0.259534 | R34: 0.21558783 | S34: 0.29031935 | T34: 0.21558783 | U34: 0.29031935 | V34: 0.21558783 | W34: 0.21558783 | X34: 0.21558783 | Y34: 0.21558783 | Z34: 0.21558783
A35: 42522 | B35: 1.2 | C35: {=ABS(pred_GDP_now!C39-pred_GDP_now!$B39)} -> 0.29031935 | D35: {=ABS(pred_GDP_now!D39-pred_GDP_now!$B39)} -> 0.307921 | E35: {=ABS(pred_GDP_now!E39-pred_GDP_now!$B39)} -> 0.35189 | F35: {=ABS(pred_GDP_now!F39-pred_GDP_now!$B39)} -> 0.308037 | G35: {=ABS(pred_GDP_now!G39-pred_GDP_now!$B39)} -> 0.848571 | H35: {=ABS(pred_GDP_now!H39-pred_GDP_now!$B39)} -> 0.13663025 | I35: {=ABS(pred_GDP_now!I39-pred_GDP_now!$B39)} -> 0.13135802 | J35: {=ABS(pred_GDP_now!J39-pred_GDP_now!$B39)} -> 0.067056 | ... P35: {=ABS(pred_GDP_now!P39-pred_GDP_now!$B39)} -> 0.066576 | R35: 0.29610279 | S35: 0.284774 | T35: 0.29610279 | U35: 0.284774 | V35: 0.29610279 | W35: 0.29610279 | X35: 0.29610279 | Y35: 0.29610279 | Z35: 0.29610279
A36: 42614 | B36: 0.4 | C36: {=ABS(pred_GDP_now!C40-pred_GDP_now!$B40)} -> 0.15010575 | D36: {=ABS(pred_GDP_now!D40-pred_GDP_now!$B40)} -> 0.241954 | E36: {=ABS(pred_GDP_now!E40-pred_GDP_now!$B40)} -> 0.163895 | F36: {=ABS(pred_GDP_now!F40-pred_GDP_now!$B40)} -> 0.284774 | G36: {=ABS(pred_GDP_now!G40-pred_GDP_now!$B40)} -> 0.536626 | H36: {=ABS(pred_GDP_now!H40-pred_GDP_now!$B40)} -> 0.55351116 | I36: {=ABS(pred_GDP_now!I40-pred_GDP_now!$B40)} -> 0.32645207 | J36: {=ABS(pred_GDP_now!J40-pred_GDP_now!$B40)} -> 0.550103 | ... P36: {=ABS(pred_GDP_now!P40-pred_GDP_now!$B40)} -> 0.042873 | R36: 0.3501465 | S36: 0.36055126 | T36: 0.3501465 | U36: 0.36611873 | V36: 0.3501465 | W36: 0.3501465 | X36: 0.3501465 | Y36: 0.3501465 | Z36: 0.3501465
A37: 42705 | B37: 0.6 | C37: {=ABS(pred_GDP_now!C41-pred_GDP_now!$B41)} -> 0.53103257 | D37: {=ABS(pred_GDP_now!D41-pred_GDP_now!$B41)} -> 0.095008 | E37: {=ABS(pred_GDP_now!E41-pred_GDP_now!$B41)} -> 0.042045 | F37: {=ABS(pred_GDP_now!F41-pred_GDP_now!$B41)} -> 0.112063 | G37: {=ABS(pred_GDP_now!G41-pred_GDP_now!$B41)} -> 0.024246 | H37: {=ABS(pred_GDP_now!H41-pred_GDP_now!$B41)} -> 0.46742764 | I37: {=ABS(pred_GDP_now!I41-pred_GDP_now!$B41)} -> 0.27291485 | J37: {=ABS(pred_GDP_now!J41-pred_GDP_now!$B41)} -> 0.445621 | ... P37: {=ABS(pred_GDP_now!P41-pred_GDP_now!$B41)} -> 0.736816 | R37: 0.086826228 | S37: 0.077116236 | T37: 0.097867 | U37: 0.077116236 | V37: 0.098026674 | W37: 0.097468831 | X37: 0.08453989 | Y37: 0.086265238 | Z37: 0.086265238
A38: 42795 | B38: 1 | C38: {=ABS(pred_GDP_now!C42-pred_GDP_now!$B42)} -> 0.077116236 | D38: {=ABS(pred_GDP_now!D42-pred_GDP_now!$B42)} -> 0.119916 | E38: {=ABS(pred_GDP_now!E42-pred_GDP_now!$B42)} -> 0.097867 | F38: {=ABS(pred_GDP_now!F42-pred_GDP_now!$B42)} -> 0.054444 | G38: {=ABS(pred_GDP_now!G42-pred_GDP_now!$B42)} -> 0.352409 | H38: {=ABS(pred_GDP_now!H42-pred_GDP_now!$B42)} -> 0.067023249 | I38: {=ABS(pred_GDP_now!I42-pred_GDP_now!$B42)} -> 0.047909378 | J38: {=ABS(pred_GDP_now!J42-pred_GDP_now!$B42)} -> 0.113357 | ... P38: {=ABS(pred_GDP_now!P42-pred_GDP_now!$B42)} -> 0.447208 | R38: 0.15854855 | S38: 0.145407 | T38: 0.308525 | U38: 0.14537621 | V38: 0.28664445 | W38: 0.28084989 | X38: 0.1790543 | Y38: 0.15738066 | Z38: 0.15818729
A39: 42887 | B39: 0.8 | C39: {=ABS(pred_GDP_now!C43-pred_GDP_now!$B43)} -> 0.29163922 | D39: {=ABS(pred_GDP_now!D43-pred_GDP_now!$B43)} -> 0.308525 | E39: {=ABS(pred_GDP_now!E43-pred_GDP_now!$B43)} -> 0.326052 | F39: {=ABS(pred_GDP_now!F43-pred_GDP_now!$B43)} -> 0.215314 | G39: {=ABS(pred_GDP_now!G43-pred_GDP_now!$B43)} -> 0.110721 | H39: {=ABS(pred_GDP_now!H43-pred_GDP_now!$B43)} -> 0.13246572 | I39: {=ABS(pred_GDP_now!I43-pred_GDP_now!$B43)} -> 0.14488392 | J39: {=ABS(pred_GDP_now!J43-pred_GDP_now!$B43)} -> 0.013014 | ... P39: {=ABS(pred_GDP_now!P43-pred_GDP_now!$B43)} -> 0.484572 | R39: 0.6921041 | S39: 0.65654105 | T39: 1.000759 | U39: 0.65681867 | V39: 0.81279673 | W39: 0.81857951 | X39: 0.78710939 | Y39: 0.70186834 | Z39: 0.68847033
A40: 42979 | B40: 1.4 | C40: {=ABS(pred_GDP_now!C44-pred_GDP_now!$B44)} -> 0.66219468 | D40: {=ABS(pred_GDP_now!D44-pred_GDP_now!$B44)} -> 1.112299 | E40: {=ABS(pred_GDP_now!E44-pred_GDP_now!$B44)} -> 1.124247 | F40: {=ABS(pred_GDP_now!F44-pred_GDP_now!$B44)} -> 1.000759 | G40: {=ABS(pred_GDP_now!G44-pred_GDP_now!$B44)} -> 0.430359 | H40: {=ABS(pred_GDP_now!H44-pred_GDP_now!$B44)} -> 0.65654105 | I40: {=ABS(pred_GDP_now!I44-pred_GDP_now!$B44)} -> 0.5652677 | J40: {=ABS(pred_GDP_now!J44-pred_GDP_now!$B44)} -> 0.439868 | ... P40: {=ABS(pred_GDP_now!P44-pred_GDP_now!$B44)} -> 0.426198 | R40: 1.0153287 | S40: 1.0193523 | T40: 1.0432521 | U40: 1.0193523 | V40: 1.0525133 | W40: 1.0493793 | X40: 1.0132568 | Y40: 1.014004 | Z40: 1.0193523
A41: 43070 | B41: -0.3 | C41: {=ABS(pred_GDP_now!C45-pred_GDP_now!$B45)} -> 1.0100969 | D41: {=ABS(pred_GDP_now!D45-pred_GDP_now!$B45)} -> 1.252379 | E41: {=ABS(pred_GDP_now!E45-pred_GDP_now!$B45)} -> 0.973771 | F41: {=ABS(pred_GDP_now!F45-pred_GDP_now!$B45)} -> 1.195778 | G41: {=ABS(pred_GDP_now!G45-pred_GDP_now!$B45)} -> 1.687553 | H41: {=ABS(pred_GDP_now!H45-pred_GDP_now!$B45)} -> 1.1721196 | I41: {=ABS(pred_GDP_now!I45-pred_GDP_now!$B45)} -> 1.1941604 | J41: {=ABS(pred_GDP_now!J45-pred_GDP_now!$B45)} -> 0.994095 | ... P41: {=ABS(pred_GDP_now!P45-pred_GDP_now!$B45)} -> 0.778414 | R41: 0.33631229 | S41: 0.362932 | T41: 0.362932 | U41: 0.35439633 | V41: 0.27896375 | W41: 0.27628188 | X41: 0.29855284 | Y41: 0.31776567 | Z41: 0.32799554
A42: 43160 | B42: 1.3 | C42: {=ABS(pred_GDP_now!C46-pred_GDP_now!$B46)} -> 0.19200216 | D42: {=ABS(pred_GDP_now!D46-pred_GDP_now!$B46)} -> 0.621278 | E42: {=ABS(pred_GDP_now!E46-pred_GDP_now!$B46)} -> 0.491907 | F42: {=ABS(pred_GDP_now!F46-pred_GDP_now!$B46)} -> 0.590313 | G42: {=ABS(pred_GDP_now!G46-pred_GDP_now!$B46)} -> 0.546515 | H42: {=ABS(pred_GDP_now!H46-pred_GDP_now!$B46)} -> 0.3224736 | I42: {=ABS(pred_GDP_now!I46-pred_GDP_now!$B46)} -> 0.29456204 | J42: {=ABS(pred_GDP_now!J46-pred_GDP_now!$B46)} -> 0.362932 | ... P42: {=ABS(pred_GDP_now!P46-pred_GDP_now!$B46)} -> 0.41661 | R42: 0.0066115275 | S42: 0.0662591 | T42: 0.12273773 | U42: 0.0662591 | V42: 0.064205868 | W42: 0.060638945 | X42: 0.0028780402 | Y42: 0.0042656669 | Z42: 0.064205868
A43: 43252 | B43: 0.7 | C43: {=ABS(pred_GDP_now!C47-pred_GDP_now!$B47)} -> 0.25959584 | D43: {=ABS(pred_GDP_now!D47-pred_GDP_now!$B47)} -> 0.011343 | E43: {=ABS(pred_GDP_now!E47-pred_GDP_now!$B47)} -> 0.147664 | F43: {=ABS(pred_GDP_now!F47-pred_GDP_now!$B47)} -> 0.001288 | G43: {=ABS(pred_GDP_now!G47-pred_GDP_now!$B47)} -> 0.38374 | H43: {=ABS(pred_GDP_now!H47-pred_GDP_now!$B47)} -> 0.13320853 | I43: {=ABS(pred_GDP_now!I47-pred_GDP_now!$B47)} -> 0.15106983 | J43: {=ABS(pred_GDP_now!J47-pred_GDP_now!$B47)} -> 0.137201 | ... P43: {=ABS(pred_GDP_now!P47-pred_GDP_now!$B47)} -> 0.103613 | R43: 0.060551647 | S43: 0.004256361 | T43: 0.004256361 | U43: 0.0035839224 | V43: 0.057856486 | W43: 0.052982565 | X43: 0.04770977 | Y43: 0.060380208 | Z43: 0.004256361
A44: 43344 | B44: 0.6 | C44: {=ABS(pred_GDP_now!C48-pred_GDP_now!$B48)} -> 0.37109739 | D44: {=ABS(pred_GDP_now!D48-pred_GDP_now!$B48)} -> 0.076312 | E44: {=ABS(pred_GDP_now!E48-pred_GDP_now!$B48)} -> 0.124334 | F44: {=ABS(pred_GDP_now!F48-pred_GDP_now!$B48)} -> 0.028576 | G44: {=ABS(pred_GDP_now!G48-pred_GDP_now!$B48)} -> 0.238222 | H44: {=ABS(pred_GDP_now!H48-pred_GDP_now!$B48)} -> 0.4800163 | I44: {=ABS(pred_GDP_now!I48-pred_GDP_now!$B48)} -> 0.44576878 | J44: {=ABS(pred_GDP_now!J48-pred_GDP_now!$B48)} -> 0.101816 | ... P44: {=ABS(pred_GDP_now!P48-pred_GDP_now!$B48)} -> 0.279481 | R44: 0.1995788 | S44: 0.24896726 | T44: 0.14688172 | U44: 0.26930122 | V44: 0.25235301 | W44: 0.24719223 | X44: 0.20413938 | Y44: 0.20000462 | Z44: 0.24853559
... A60: 44805 | B60: 0.2 | C60: {=ABS(pred_GDP_now!C64-pred_GDP_now!$B64)} -> 0.23518209 | D60: {=ABS(pred_GDP_now!D64-pred_GDP_now!$B64)} -> 7.2e-05 | E60: {=ABS(pred_GDP_now!E64-pred_GDP_now!$B64)} -> 0.104746 | F60: {=ABS(pred_GDP_now!F64-pred_GDP_now!$B64)} -> 0.140619 | G60: {=ABS(pred_GDP_now!G64-pred_GDP_now!$B64)} -> 0.84117 | H60: {=ABS(pred_GDP_now!H64-pred_GDP_now!$B64)} -> 0.089937769 | I60: {=ABS(pred_GDP_now!I64-pred_GDP_now!$B64)} -> 0.22239781 | J60: {=ABS(pred_GDP_now!J64-pred_GDP_now!$B64)} -> 0.673112 | ... P60: {=ABS(pred_GDP_now!P64-pred_GDP_now!$B64)} -> 0.396038 | R60: 0.030880136 | S60: 0.13845 | T60: 0.48486 | U60: 0.2460993 | V60: 0.36991821 | W60: 0.36253581 | X60: 0.11945348 | Y60: 0.032630483 | Z60: 0.21199164
A61: 44896 | B61: -0.3 | C61: {=ABS(pred_GDP_now!C65-pred_GDP_now!$B65)} -> 0.50932658 | D61: {=ABS(pred_GDP_now!D65-pred_GDP_now!$B65)} -> 0.48486 | E61: {=ABS(pred_GDP_now!E65-pred_GDP_now!$B65)} -> 0.63253 | F61: {=ABS(pred_GDP_now!F65-pred_GDP_now!$B65)} -> 0.25036 | G61: {=ABS(pred_GDP_now!G65-pred_GDP_now!$B65)} -> 0.26236 | H61: {=ABS(pred_GDP_now!H65-pred_GDP_now!$B65)} -> 0.30430739 | I61: {=ABS(pred_GDP_now!I65-pred_GDP_now!$B65)} -> 0.75885565 | J61: {=ABS(pred_GDP_now!J65-pred_GDP_now!$B65)} -> 0.13845 | ... P61: {=ABS(pred_GDP_now!P65-pred_GDP_now!$B65)} -> 0.135121 | R61: {=ABS(pred_GDP_now!R65-pred_GDP_now!$B65)} -> 0.040736025 | S61: {=ABS(pred_GDP_now!S65-pred_GDP_now!$B65)} -> 0.135121 | T61: {=ABS(pred_GDP_now!T65-pred_GDP_now!$B65)} -> 0.48486 | U61: {=ABS(pred_GDP_now!U65-pred_GDP_now!$B65)} -> 0.33194467 | V61: {=ABS(pred_GDP_now!V65-pred_GDP_now!$B65)} -> 0.56153551 | W61: {=ABS(pred_GDP_now!W65-pred_GDP_now!$B65)} -> 0.51073761 | X61: {=ABS(pred_GDP_now!X65-pred_GDP_now!$B65)} -> 0.16786763 | Y61: {=ABS(pred_GDP_now!Y65-pred_GDP_now!$B65)} -> 0.05269366 | Z61: {=ABS(pred_GDP_now!Z65-pred_GDP_now!$B65)} -> 0.18237347
A64: MAE
A65: 전기간(08~22) | D65: {=AVERAGE(D2:D61)} -> 0.59523926 | E65: {=AVERAGE(E2:E61)} -> 0.58880662 | K65: {=AVERAGE(K2:K61)} -> 0.46519128 | M65: {=AVERAGE(M2:M61)} -> 0.53907487 | N65: {=AVERAGE(N2:N61)} -> 0.52680481 | O65: {=AVERAGE(O2:O61)} -> 0.53933569 | P65: {=AVERAGE(P2:P61)} -> 0.52934706 | R65: {=AVERAGE(R2:R61)} -> 0.4411353 | S65: {=AVERAGE(S2:S61)} -> 0.46608879 | T65: {=AVERAGE(T2:T61)} -> 0.50609225 | U65: {=AVERAGE(U2:U61)} -> 0.42020278 | V65: {=AVERAGE(V2:V61)} -> 0.47872546 | W65: {=AVERAGE(W2:W61)} -> 0.47674736 | X65: {=AVERAGE(X2:X61)} -> 0.45239504 | Y65: {=AVERAGE(Y2:Y61)} -> 0.44087882 | Z65: {=AVERAGE(Z2:Z61)} -> 0.38118688
A66: GFC(08~09) | D66: {=AVERAGE(D2:D9)} -> 1.3979041 | E66: {=AVERAGE(E2:E9)} -> 1.6496048 | K66: {=AVERAGE(K2:K9)} -> 1.158683 | M66: {=AVERAGE(M2:M9)} -> 1.078367 | N66: {=AVERAGE(N2:N9)} -> 1.2102233 | O66: {=AVERAGE(O2:O9)} -> 0.82927164 | P66: {=AVERAGE(P2:P9)} -> 1.1363429 | R66: {=AVERAGE(R2:R9)} -> 1.0966361 | S66: {=AVERAGE(S2:S9)} -> 1.1687753 | T66: {=AVERAGE(T2:T9)} -> 1.2479271 | U66: {=AVERAGE(U2:U9)} -> 0.91356362 | V66: {=AVERAGE(V2:V9)} -> 1.2140598 | W66: {=AVERAGE(W2:W9)} -> 1.2129703 | X66: {=AVERAGE(X2:X9)} -> 1.1042723 | Y66: {=AVERAGE(Y2:Y9)} -> 1.0916548 | Z66: {=AVERAGE(Z2:Z9)} -> 0.80596899

Sheet pred_GDP_1qa
B1: GDP(SA) True | C1: DFM | D1: BEM1 | E1: BEM2 | F1: BEM3 | G1: LBVAR | H1: TFM | I1: T-M | J1: VAR | K1: SVR-KNN | L1: CRNN | M1: RF-DVS | N1: S-XGB | O1: LQR | P1: OptimARIMA | R1: Avg | S1: Med | T1: AdaMSM | U1: DQS | V1: BMA | W1: DMA | X1: LOP | Y1: AFTER | Z1: DQS_Mk2
A2: 39142 | B2: 1.8 | C2: =NA() -> #N/A | D2: 0.86442714 | E2: 1.2301931 | F2: =NA() -> #N/A | G2: =NA() -> #N/A | H2: =NA() -> #N/A | I2: =NA() -> #N/A | J2: =NA() -> #N/A | K2: 0.85574178 | L2: =NA() -> #N/A | M2: 1.2303641 | N2: 1.3876349 | O2: 0.046404608 | P2: -0.051158263 | R2: 0.79480106 | S2: 0.86442714 | T2: 0.79480106 | U2: 0.86442714 | V2: 0.79480106 | W2: 0.79480106 | X2: 0.79480106 | Y2: 0.79480106 | Z2: 0.79480106
A3: 39234 | B3: 1.7 | C3: =NA() -> #N/A | D3: 1.4248629 | E3: 1.1242106 | F3: =NA() -> #N/A | G3: =NA() -> #N/A | H3: =NA() -> #N/A | I3: =NA() -> #N/A | J3: =NA() -> #N/A | K3: 1.0734972 | L3: =NA() -> #N/A | M3: 1.1206925 | N3: 1.3003066 | O3: 0.51408001 | P3: 2.5377584 | R3: 1.299344 | S3: 1.1242106 | T3: 1.299344 | U3: 1.1242106 | V3: 1.299344 | W3: 1.299344 | X3: 1.299344 | Y3: 1.299344 | Z3: 2.5377584
A4: 39326 | B4: 1.2 | C4: =NA() -> #N/A | D4: 1.0936434 | E4: 1.0912067 | F4: =NA() -> #N/A | G4: =NA() -> #N/A | H4: =NA() -> #N/A | I4: =NA() -> #N/A | J4: =NA() -> #N/A | K4: 1.0670952 | L4: =NA() -> #N/A | M4: 1.2356663 | N4: 1.3452915 | O4: 0.52405204 | P4: 1.3545633 | R4: 1.1016455 | S4: 1.0936434 | T4: 1.1016455 | U4: 1.0936434 | V4: 1.1016455 | W4: 1.1016455 | X4: 1.1016455 | Y4: 1.1016455 | Z4: 1.1016455
A5: 39417 | B5: 2 | C5: =NA() -> #N/A | D5: 0.96044935 | E5: 0.86325001 | F5: =NA() -> #N/A | G5: =NA() -> #N/A | H5: =NA() -> #N/A | I5: =NA() -> #N/A | J5: =NA() -> #N/A | K5: 0.83776121 | L5: =NA() -> #N/A | M5: 1.1811188 | N5: 1.3864248 | O5: -0.1460407 | P5: 0.46173778 | R5: 0.79210018 | S5: 0.86325001 | T5: 0.79210018 | U5: 0.7476338 | V5: 0.79210018 | W5: 0.79210018 | X5: 0.79210018 | Y5: 0.79210018 | Z5: 0.79210018
A6: 39508 | B6: 0.8 | C6: =NA() -> #N/A | D6: 1.1778929 | E6: 0.88547617 | F6: =NA() -> #N/A | G6: =NA() -> #N/A | H6: =NA() -> #N/A | I6: =NA() -> #N/A | J6: =NA() -> #N/A | K6: 1.1861417 | L6: =NA() -> #N/A | M6: 0.97026939 | N6: 1.3644819 | O6: -0.12445399 | P6: -0.09201647 | R6: 0.76682738 | S6: 0.97026939 | T6: 1.1778929 | U6: 0.97026939 | V6: 0.98723003 | W6: 0.97978048 | X6: 1.0777188 | Y6: 1.0273638 | Z6: 1.1778929
A7: 39600 | B7: 0.4 | C7: =NA() -> #N/A | D7: 0.58763549 | E7: 0.47440268 | F7: =NA() -> #N/A | G7: =NA() -> #N/A | H7: =NA() -> #N/A | I7: =NA() -> #N/A | J7: =NA() -> #N/A | K7: 1.340698 | L7: =NA() -> #N/A | M7: 1.0854291 | N7: 1.4444939 | O7: 0.7145496 | P7: 0.16892145 | R7: 0.83087574 | S7: 0.7145496 | T7: 1.0854291 | U7: 0.7145496 | V7: 0.93794569 | W7: 0.93394854 | X7: 0.97289932 | Y7: 0.90976377 | Z7: 0.87192321
A8: 39692 | B8: 0.7 | C8: =NA() -> #N/A | D8: 1.1506634 | E8: 1.0454433 | F8: =NA() -> #N/A | G8: =NA() -> #N/A | H8: =NA() -> #N/A | I8: =NA() -> #N/A | J8: =NA() -> #N/A | K8: 0.71022351 | L8: =NA() -> #N/A | M8: 0.85491885 | N8: 1.3672147 | O8: -0.22571921 | P8: 1.1573917 | R8: 0.86573375 | S8: 1.0454433 | T8: 1.0454433 | U8: 1.0454433 | V8: 1.0332428 | W8: 1.0314723 | X8: 0.98872315 | Y8: 0.97689481 | Z8: 1.0332428
A9: 39783 | B9: -3.4 | C9: =NA() -> #N/A | D9: 1.4961726 | E9: 1.2268586 | F9: =NA() -> #N/A | G9: =NA() -> #N/A | H9: =NA() -> #N/A | I9: =NA() -> #N/A | J9: =NA() -> #N/A | K9: 1.1488182 | L9: =NA() -> #N/A | M9: 0.71528838 | N9: 1.3194889 | O9: -0.4370661 | P9: 1.3848517 | R9: 0.97920176 | S9: 1.2268586 | T9: 1.2268586 | U9: 1.1811448 | V9: 1.1523655 | W9: 1.1518298 | X9: 1.1000458 | Y9: 1.1109986 | Z9: 1.1523655
A10: 39873 | B10: 0.3 | C10: =NA() -> #N/A | D10: 1.7321628 | E10: 1.287871 | F10: =NA() -> #N/A | G10: =NA() -> #N/A | H10: =NA() -> #N/A | I10: =NA() -> #N/A | J10: =NA() -> #N/A | K10: 1.5367914 | L10: =NA() -> #N/A | M10: 0.79394187 | N10: 1.284721 | O10: -1.6762802 | P10: 0.8907616 | R10: 0.83570993 | S10: 1.284721 | T10: 0.79394187 | U10: 1.0877413 | V10: 0.37015906 | W10: 0.39846199 | X10: 0.48657282 | Y10: -0.87029812 | Z10: -1.6762802
A11: 39965 | B11: 1.4 | C11: =NA() -> #N/A | D11: 3.9445536 | E11: 3.8739052 | F11: =NA() -> #N/A | G11: =NA() -> #N/A | H11: =NA() -> #N/A | I11: =NA() -> #N/A | J11: =NA() -> #N/A | K11: 1.7849668 | L11: =NA() -> #N/A | M11: 1.2974803 | N11: 1.2126155 | O11: 1.2458616 | P11: 0.5336309 | R11: 1.9847163 | S11: 1.2974803 | T11: 1.2974803 | U11: 1.2974803 | V11: 1.7662131 | W11: 1.7777992 | X11: 1.8783053 | Y11: 1.4782136 | Z11: 1.4782136
A12: 40057 | B12: 3.1 | C12: =NA() -> #N/A | D12: 1.2025278 | E12: 1.3241491 | F12: =NA() -> #N/A | G12: =NA() -> #N/A | H12: =NA() -> #N/A | I12: =NA() -> #N/A | J12: =NA() -> #N/A | K12: 1.3512801 | L12: =NA() -> #N/A | M12: 1.154839 | N12: 1.2717134 | O12: 0.19109417 | P12: 0.85574655 | R12: 1.0501929 | S12: 1.2025278 | T12: 1.154839 | U12: 1.1786834 | V12: 0.97174795 | W12: 0.97607775 | X12: 0.96337706 | Y12: 0.59398597 | Z12: 1.154839
A13: 40148 | B13: 0.7 | C13: =NA() -> #N/A | D13: 0.53964978 | E13: 2.2387659 | F13: =NA() -> #N/A | G13: =NA() -> #N/A | H13: =NA() -> #N/A | I13: =NA() -> #N/A | J13: =NA() -> #N/A | K13: 1.2690578 | L13: =NA() -> #N/A | M13: 1.2310782 | N13: 1.2703278 | O13: 0.53382568 | P13: 1.3328419 | R13: 1.202221 | S13: 1.2690578 | T13: 1.2690578 | U13: 1.2690578 | V13: 1.1630816 | W13: 1.1655945 | X13: 1.1791647 | Y13: 1.0222216 | Z13: 1.2310782
... A38: 42430 | B38: 0.3 | C38: =NA() -> #N/A | D38: 0.8274774 | E38: 1.0817977 | F38: =NA() -> #N/A | G38: =NA() -> #N/A | H38: =NA() -> #N/A | I38: =NA() -> #N/A | J38: =NA() -> #N/A | K38: 0.76611712 | L38: =NA() -> #N/A | M38: 0.74429481 | N38: 0.75382519 | O38: 0.12474304 | P38: 0.34360977 | R38: 0.66312358 | S38: 0.75382519 | T38: 0.76611712 | U38: 0.75382519 | V38: 0.76182684 | W38: 0.76101683 | X38: 0.73442749 | Y38: 0.70277765 | Z38: 0.75382519
A39: 42522 | B39: 1.2 | C39: 0.52187 | D39: 0.68174 | E39: 0.60908 | F39: 0.40931 | G39: =NA() -> #N/A | H39: 1.07836 | I39: 0.98704 | J39: -0.03484 | K39: 0.85592 | L39: 0.8 | M39: 0.79073 | N39: 1.10469 | O39: 0.64991 | P39: 0.98634 | R39: 0.72616538 | S39: 0.79073 | T39: 0.72616538 | U39: 0.79073 | V39: 0.72616538 | W39: 0.72616538 | X39: 0.72616538 | Y39: 0.72616538 | Z39: 0.72616538
A40: 42614 | B40: 0.4 | C40: 0.78732 | D40: 0.45251 | E40: 0.44079 | F40: 0.64712 | G40: =NA() -> #N/A | H40: 1.04601 | I40: 0.88749 | J40: 0.41444 | K40: 0.50364 | L40: 0.8 | M40: 0.40579 | N40: 1.13505 | O40: 0.68819 | P40: 1.01989 | R40: 0.70986462 | S40: 0.68819 | T40: 0.70986462 | U40: 0.68819 | V40: 0.70986462 | W40: 0.70986462 | X40: 0.70986462 | Y40: 0.70986462 | Z40: 0.40579
A41: 42705 | B41: 0.6 | C41: 0.61676 | D41: 0.46307 | E41: 0.39906 | F41: 0.68148 | G41: =NA() -> #N/A | H41: 0.55462 | I41: 0.66955 | J41: 0.2402 | K41: 0.69038 | L41: 0.7 | M41: 0.52939 | N41: 1.24686 | O41: 0.6308 | P41: 0.85448 | R41: 0.63666538 | S41: 0.6308 | T41: 0.63666538 | U41: 0.6308 | V41: 0.63666538 | W41: 0.63666538 | X41: 0.63666538 | Y41: 0.63666538 | Z41: 0.63666538
A42: 42795 | B42: 1 | C42: 1.08965 | D42: 0.91609 | E42: 0.87749 | F42: 0.7858 | G42: =NA() -> #N/A | H42: 1.34307 | I42: 1.09835 | J42: 0.10692 | K42: 0.18384 | L42: 0.8 | M42: 0.67763 | N42: 1.24222 | O42: 0.98542 | P42: 1.15928 | R42: 0.86659692 | S42: 0.91609 | T42: 0.86659692 | U42: 0.88531361 | V42: 0.86659692 | W42: 0.86659692 | X42: 0.86659692 | Y42: 0.86659692 | Z42: 0.87374501
A43: 42887 | B43: 0.8 | C43: 0.70762 | D43: 0.46973 | E43: 0.4502 | F43: 0.85792 | G43: =NA() -> #N/A | H43: 1.04835 | I43: 1.08067 | J43: 0.40665 | K43: -0.35811 | L43: 0.6 | M43: 0.40989 | N43: 1.00121 | O43: 0.77855 | P43: 1.23765 | R43: 0.66848692 | S43: 0.70762 | T43: 0.46973 | U43: 0.51927274 | V43: 0.6745311 | W43: 0.67633941 | X43: 0.68253373 | Y43: 0.67701685 | Z43: 0.67535939
A44: 42979 | B44: 1.4 | C44: 0.92213 | D44: 0.50071 | E44: 0.44908 | F44: 0.91336 | G44: =NA() -> #N/A | H44: 0.58606 | I44: 0.7164 | J44: 0.12469 | K44: 0.24672 | L44: 1.1 | M44: 0.45234 | N44: 0.91079 | O44: 0.84539 | P44: 1.21857 | R44: 0.69124923 | S44: 0.7164 | T44: 0.91336 | U44: 0.71593571 | V44: 0.75219789 | W44: 0.75159837 | X44: 0.74964791 | Y44: 0.70694507 | Z44: 0.72894349
A45: 43070 | B45: -0.3 | C45: 0.97254 | D45: 0.54775 | E45: 0.46282 | F45: 0.43926 | G45: =NA() -> #N/A | H45: 0.98617 | I45: 1.05751 | J45: 0.08409 | K45: 0.42294 | L45: 0.9 | M45: 0.50967 | N45: 1.2478 | O45: 0.84938 | P45: 1.12079 | R45: 0.73851692 | S45: 0.84938 | T45: 0.9 | U45: 0.84962573 | V45: 0.87033076 | W45: 0.86921792 | X45: 0.84661975 | Y45: 0.78168733 | Z45: 0.85083178
A46: 43160 | B46: 1.3 | C46: 0.92491 | D46: 0.66942 | E46: 0.61394 | F46: 0.97133 | G46: =NA() -> #N/A | H46: 0.83767 | I46: 0.79708 | J46: 0.20646 | K46: 0.63152 | L46: 1.1 | M46: 0.66631 | N46: 0.87301 | O46: 0.54878 | P46: 0.77248 | R46: 0.73945462 | S46: 0.77248 | T46: 0.97133 | U46: 0.77248 | V46: 0.91757988 | W46: 0.91012944 | X46: 0.77201107 | Y46: 0.75255443 | Z46: 0.77248
A47: 43252 | B47: 0.7 | C47: 0.61097 | D47: 0.6894 | E47: 0.65111 | F47: 0.51504 | G47: =NA() -> #N/A | H47: 0.33402 | I47: 0.49375 | J47: 0.27147 | K47: 0.48024 | L47: 0.6 | M47: 0.57425 | N47: 0.78232 | O47: 0.66345 | P47: 1.00266 | R47: 0.58989846 | S47: 0.6 | T47: 0.6 | U47: 0.6 | V47: 0.5234081 | W47: 0.52599077 | X47: 0.59014132 | Y47: 0.59393043 | Z47: 0.59393043
A48: 43344 | B48: 0.6 | C48: 1.04818 | D48: 0.60773 | E48: 0.56543 | F48: 0.79571 | G48: =NA() -> #N/A | H48: 1.27524 | I48: 0.92319 | J48: 0.19797 | K48: 0.64221 | L48: 0.8 | M48: 0.57913 | N48: 1.46176 | O48: 0.6069 | P48: 0.84057 | R48: 0.79569385 | S48: 0.79571 | T48: 0.8 | U48: 0.79590816 | V48: 0.79481614 | W48: 0.79456895 | X48: 0.78743552 | Y48: 0.79128326 | Z48: 0.79569699
A49: 43435 | B49: 0.6 | C49: 0.5419 | D49: 0.50534 | E49: 0.4468 | F49: 0.53214 | G49: =NA() -> #N/A | H49: 0.33282 | I49: 0.51763 | J49: 0.0952 | K49: 0.73619 | L49: 0.7 | M49: 0.51361 | N49: 0.95077 | O49: 0.97005 | P49: 0.71429 | R49: 0.58128769 | S49: 0.53214 | T49: 0.50534 | U49: 0.53214 | V49: 0.54757872 | W49: 0.54780235 | X49: 0.56319718 | Y49: 0.57072616 | Z49: 0.5419
A50: 43525 | B50: -0.1 | C50: 0.57776 | D50: 0.39509 | E50: 0.33361 | F50: 0.24953 | G50: =NA() -> #N/A | H50: 0.5622 | I50: 0.61188 | J50: -0.1897 | K50: -0.52494 | L50: 0.7 | M50: 0.68929 | N50: 0.61863 | O50: 0.66243 | P50: 0.53445 | R50: 0.40155615 | S50: 0.5622 | T50: 0.39509 | U50: 0.53986871 | V50: 0.55438777 | W50: 0.54868081 | X50: 0.47530319 | Y50: 0.41327866 | Z50: 0.54525568
... A66: 44986 | B66: 0.3 | C66: 0.62315 | D66: 0.39904 | E66: 0.32492 | F66: -0.28481 | G66: =NA() -> #N/A | H66: 0.07608 | I66: 0.6327 | J66: -0.17197 | K66: 0.89374 | L66: 0.5 | M66: 0.76027 | N66: 0.39814 | O66: 0.3877 | P66: 0.52064 | R66: 0.3892 | S66: 0.39904 | T66: 0.07608 | U66: 0.39859 | V66: 0.021833518 | W66: 0.029918297 | X66: 0.23491955 | Y66: 0.35570657 | Z66: 0.38790349

Sheet error_1qa
B1: GDP(SA) True | C1: DFM | D1: BEM1 | E1: BEM2 | F1: BEM3 | G1: LBVAR | H1: TFM | I1: T-M | J1: VAR | K1: SVR-KNN | L1: CRNN | M1: RF-DVS | N1: S-XGB | O1: LQR | P1: OptimARIMA | R1: Avg | S1: Med | T1: AdaMSM | U1: DQS | V1: BMA | W1: DMA | X1: LOP | Y1: AFTER | Z1: DQS_Mk2
A2: 39508 | B2: 0.8 | C2: {=ABS(pred_GDP_1qa!C6-pred_GDP_1qa!$B6)} -> #N/A | D2: {=ABS(pred_GDP_1qa!D6-pred_GDP_1qa!$B6)} -> 0.37789289 | E2: {=ABS(pred_GDP_1qa!E6-pred_GDP_1qa!$B6)} -> 0.085476173 | F2: {=ABS(pred_GDP_1qa!F6-pred_GDP_1qa!$B6)} -> #N/A | G2: {=ABS(pred_GDP_1qa!G6-pred_GDP_1qa!$B6)} -> #N/A | H2: {=ABS(pred_GDP_1qa!H6-pred_GDP_1qa!$B6)} -> #N/A | I2: {=ABS(pred_GDP_1qa!I6-pred_GDP_1qa!$B6)} -> #N/A | J2: {=ABS(pred_GDP_1qa!J6-pred_GDP_1qa!$B6)} -> #N/A | ... P2: {=ABS(pred_GDP_1qa!P6-pred_GDP_1qa!$B6)} -> 0.89201647 | R2: {=ABS(pred_GDP_1qa!R6-pred_GDP_1qa!$B6)} -> 0.033172624 | S2: {=ABS(pred_GDP_1qa!S6-pred_GDP_1qa!$B6)} -> 0.17026939 | T2: {=ABS(pred_GDP_1qa!T6-pred_GDP_1qa!$B6)} -> 0.37789289 | U2: {=ABS(pred_GDP_1qa!U6-pred_GDP_1qa!$B6)} -> 0.17026939 | V2: {=ABS(pred_GDP_1qa!V6-pred_GDP_1qa!$B6)} -> 0.18723003 | W2: {=ABS(pred_GDP_1qa!W6-pred_GDP_1qa!$B6)} -> 0.17978048 | X2: {=ABS(pred_GDP_1qa!X6-pred_GDP_1qa!$B6)} -> 0.27771883 | Y2: {=ABS(pred_GDP_1qa!Y6-pred_GDP_1qa!$B6)} -> 0.22736384 | Z2: {=ABS(pred_GDP_1qa!Z6-pred_GDP_1qa!$B6)} -> 0.37789289
A3: 39600 | B3: 0.4 | C3: {=ABS(pred_GDP_1qa!C7-pred_GDP_1qa!$B7)} -> #N/A | D3: {=ABS(pred_GDP_1qa!D7-pred_GDP_1qa!$B7)} -> 0.18763549 | E3: {=ABS(pred_GDP_1qa!E7-pred_GDP_1qa!$B7)} -> 0.074402684 | F3: {=ABS(pred_GDP_1qa!F7-pred_GDP_1qa!$B7)} -> #N/A | G3: {=ABS(pred_GDP_1qa!G7-pred_GDP_1qa!$B7)} -> #N/A | H3: {=ABS(pred_GDP_1qa!H7-pred_GDP_1qa!$B7)} -> #N/A | I3: {=ABS(pred_GDP_1qa!I7-pred_GDP_1qa!$B7)} -> #N/A | J3: {=ABS(pred_GDP_1qa!J7-pred_GDP_1qa!$B7)} -> #N/A | ... P3: {=ABS(pred_GDP_1qa!P7-pred_GDP_1qa!$B7)} -> 0.23107855 | R3: {=ABS(pred_GDP_1qa!R7-pred_GDP_1qa!$B7)} -> 0.43087574 | S3: {=ABS(pred_GDP_1qa!S7-pred_GDP_1qa!$B7)} -> 0.3145496 | T3: {=ABS(pred_GDP_1qa!T7-pred_GDP_1qa!$B7)} -> 0.68542905 | U3: {=ABS(pred_GDP_1qa!U7-pred_GDP_1qa!$B7)} -> 0.3145496 | V3: {=ABS(pred_GDP_1qa!V7-pred_GDP_1qa!$B7)} -> 0.53794569 | W3: {=ABS(pred_GDP_1qa!W7-pred_GDP_1qa!$B7)} -> 0.53394854 | X3: {=ABS(pred_GDP_1qa!X7-pred_GDP_1qa!$B7)} -> 0.57289932 | Y3: {=ABS(pred_GDP_1qa!Y7-pred_GDP_1qa!$B7)} -> 0.50976377 | Z3: {=ABS(pred_GDP_1qa!Z7-pred_GDP_1qa!$B7)} -> 0.47192321
A4: 39692 | B4: 0.7 | C4: {=ABS(pred_GDP_1qa!C8-pred_GDP_1qa!$B8)} -> #N/A | D4: {=ABS(pred_GDP_1qa!D8-pred_GDP_1qa!$B8)} -> 0.45066343 | E4: {=ABS(pred_GDP_1qa!E8-pred_GDP_1qa!$B8)} -> 0.34544332 | F4: {=ABS(pred_GDP_1qa!F8-pred_GDP_1qa!$B8)} -> #N/A | G4: {=ABS(pred_GDP_1qa!G8-pred_GDP_1qa!$B8)} -> #N/A | H4: {=ABS(pred_GDP_1qa!H8-pred_GDP_1qa!$B8)} -> #N/A | I4: {=ABS(pred_GDP_1qa!I8-pred_GDP_1qa!$B8)} -> #N/A | J4: {=ABS(pred_GDP_1qa!J8-pred_GDP_1qa!$B8)} -> #N/A | ... P4: {=ABS(pred_GDP_1qa!P8-pred_GDP_1qa!$B8)} -> 0.45739165 | R4: {=ABS(pred_GDP_1qa!R8-pred_GDP_1qa!$B8)} -> 0.16573375 | S4: {=ABS(pred_GDP_1qa!S8-pred_GDP_1qa!$B8)} -> 0.34544332 | T4: {=ABS(pred_GDP_1qa!T8-pred_GDP_1qa!$B8)} -> 0.34544332 | U4: {=ABS(pred_GDP_1qa!U8-pred_GDP_1qa!$B8)} -> 0.34544332 | V4: {=ABS(pred_GDP_1qa!V8-pred_GDP_1qa!$B8)} -> 0.33324277 | W4: {=ABS(pred_GDP_1qa!W8-pred_GDP_1qa!$B8)} -> 0.33147229 | X4: {=ABS(pred_GDP_1qa!X8-pred_GDP_1qa!$B8)} -> 0.28872315 | Y4: {=ABS(pred_GDP_1qa!Y8-pred_GDP_1qa!$B8)} -> 0.27689481 | Z4: {=ABS(pred_GDP_1qa!Z8-pred_GDP_1qa!$B8)} -> 0.33324277
A5: 39783 | B5: -3.4 | C5: {=ABS(pred_GDP_1qa!C9-pred_GDP_1qa!$B9)} -> #N/A | D5: {=ABS(pred_GDP_1qa!D9-pred_GDP_1qa!$B9)} -> 4.8961726 | E5: {=ABS(pred_GDP_1qa!E9-pred_GDP_1qa!$B9)} -> 4.6268586 | F5: {=ABS(pred_GDP_1qa!F9-pred_GDP_1qa!$B9)} -> #N/A | G5: {=ABS(pred_GDP_1qa!G9-pred_GDP_1qa!$B9)} -> #N/A | H5: {=ABS(pred_GDP_1qa!H9-pred_GDP_1qa!$B9)} -> #N/A | I5: {=ABS(pred_GDP_1qa!I9-pred_GDP_1qa!$B9)} -> #N/A | J5: {=ABS(pred_GDP_1qa!J9-pred_GDP_1qa!$B9)} -> #N/A | ... P5: {=ABS(pred_GDP_1qa!P9-pred_GDP_1qa!$B9)} -> 4.7848517 | R5: {=ABS(pred_GDP_1qa!R9-pred_GDP_1qa!$B9)} -> 4.3792018 | S5: {=ABS(pred_GDP_1qa!S9-pred_GDP_1qa!$B9)} -> 4.6268586 | T5: {=ABS(pred_GDP_1qa!T9-pred_GDP_1qa!$B9)} -> 4.6268586 | U5: {=ABS(pred_GDP_1qa!U9-pred_GDP_1qa!$B9)} -> 4.5811448 | V5: {=ABS(pred_GDP_1qa!V9-pred_GDP_1qa!$B9)} -> 4.5523655 | W5: {=ABS(pred_GDP_1qa!W9-pred_GDP_1qa!$B9)} -> 4.5518298 | X5: {=ABS(pred_GDP_1qa!X9-pred_GDP_1qa!$B9)} -> 4.5000458 | Y5: {=ABS(pred_GDP_1qa!Y9-pred_GDP_1qa!$B9)} -> 4.5109986 | Z5: {=ABS(pred_GDP_1qa!Z9-pred_GDP_1qa!$B9)} -> 4.5523655
A6: 39873 | B6: 0.3 | C6: {=ABS(pred_GDP_1qa!C10-pred_GDP_1qa!$B10)} -> #N/A | D6: {=ABS(pred_GDP_1qa!D10-pred_GDP_1qa!$B10)} -> 1.4321628 | E6: {=ABS(pred_GDP_1qa!E10-pred_GDP_1qa!$B10)} -> 0.98787104 | F6: {=ABS(pred_GDP_1qa!F10-pred_GDP_1qa!$B10)} -> #N/A | G6: {=ABS(pred_GDP_1qa!G10-pred_GDP_1qa!$B10)} -> #N/A | H6: {=ABS(pred_GDP_1qa!H10-pred_GDP_1qa!$B10)} -> #N/A | I6: {=ABS(pred_GDP_1qa!I10-pred_GDP_1qa!$B10)} -> #N/A | J6: {=ABS(pred_GDP_1qa!J10-pred_GDP_1qa!$B10)} -> #N/A | ... P6: {=ABS(pred_GDP_1qa!P10-pred_GDP_1qa!$B10)} -> 0.5907616 | R6: {=ABS(pred_GDP_1qa!R10-pred_GDP_1qa!$B10)} -> 0.53570993 | S6: {=ABS(pred_GDP_1qa!S10-pred_GDP_1qa!$B10)} -> 0.98472102 | T6: {=ABS(pred_GDP_1qa!T10-pred_GDP_1qa!$B10)} -> 0.49394187 | U6: {=ABS(pred_GDP_1qa!U10-pred_GDP_1qa!$B10)} -> 0.78774131 | V6: {=ABS(pred_GDP_1qa!V10-pred_GDP_1qa!$B10)} -> 0.07015906 | W6: {=ABS(pred_GDP_1qa!W10-pred_GDP_1qa!$B10)} -> 0.098461989 | X6: {=ABS(pred_GDP_1qa!X10-pred_GDP_1qa!$B10)} -> 0.18657282 | Y6: {=ABS(pred_GDP_1qa!Y10-pred_GDP_1qa!$B10)} -> 1.1702981 | Z6: {=ABS(pred_GDP_1qa!Z10-pred_GDP_1qa!$B10)} -> 1.9762802
A7: 39965 | B7: 1.4 | C7: {=ABS(pred_GDP_1qa!C11-pred_GDP_1qa!$B11)} -> #N/A | D7: {=ABS(pred_GDP_1qa!D11-pred_GDP_1qa!$B11)} -> 2.5445536 | E7: {=ABS(pred_GDP_1qa!E11-pred_GDP_1qa!$B11)} -> 2.4739052 | F7: {=ABS(pred_GDP_1qa!F11-pred_GDP_1qa!$B11)} -> #N/A | G7: {=ABS(pred_GDP_1qa!G11-pred_GDP_1qa!$B11)} -> #N/A | H7: {=ABS(pred_GDP_1qa!H11-pred_GDP_1qa!$B11)} -> #N/A | I7: {=ABS(pred_GDP_1qa!I11-pred_GDP_1qa!$B11)} -> #N/A | J7: {=ABS(pred_GDP_1qa!J11-pred_GDP_1qa!$B11)} -> #N/A | ... P7: {=ABS(pred_GDP_1qa!P11-pred_GDP_1qa!$B11)} -> 0.8663691 | R7: {=ABS(pred_GDP_1qa!R11-pred_GDP_1qa!$B11)} -> 0.58471627 | S7: {=ABS(pred_GDP_1qa!S11-pred_GDP_1qa!$B11)} -> 0.10251973 | T7: {=ABS(pred_GDP_1qa!T11-pred_GDP_1qa!$B11)} -> 0.10251973 | U7: {=ABS(pred_GDP_1qa!U11-pred_GDP_1qa!$B11)} -> 0.10251973 | V7: {=ABS(pred_GDP_1qa!V11-pred_GDP_1qa!$B11)} -> 0.36621311 | W7: {=ABS(pred_GDP_1qa!W11-pred_GDP_1qa!$B11)} -> 0.37779919 | X7: {=ABS(pred_GDP_1qa!X11-pred_GDP_1qa!$B11)} -> 0.47830535 | Y7: {=ABS(pred_GDP_1qa!Y11-pred_GDP_1qa!$B11)} -> 0.078213627 | Z7: {=ABS(pred_GDP_1qa!Z11-pred_GDP_1qa!$B11)} -> 0.078213627
A8: 40057 | B8: 3.1 | C8: {=ABS(pred_GDP_1qa!C12-pred_GDP_1qa!$B12)} -> #N/A | D8: {=ABS(pred_GDP_1qa!D12-pred_GDP_1qa!$B12)} -> 1.8974722 | E8: {=ABS(pred_GDP_1qa!E12-pred_GDP_1qa!$B12)} -> 1.7758509 | F8: {=ABS(pred_GDP_1qa!F12-pred_GDP_1qa!$B12)} -> #N/A | G8: {=ABS(pred_GDP_1qa!G12-pred_GDP_1qa!$B12)} -> #N/A | H8: {=ABS(pred_GDP_1qa!H12-pred_GDP_1qa!$B12)} -> #N/A | I8: {=ABS(pred_GDP_1qa!I12-pred_GDP_1qa!$B12)} -> #N/A | J8: {=ABS(pred_GDP_1qa!J12-pred_GDP_1qa!$B12)} -> #N/A | ... P8: {=ABS(pred_GDP_1qa!P12-pred_GDP_1qa!$B12)} -> 2.2442534 | R8: {=ABS(pred_GDP_1qa!R12-pred_GDP_1qa!$B12)} -> 2.0498071 | S8: {=ABS(pred_GDP_1qa!S12-pred_GDP_1qa!$B12)} -> 1.8974722 | T8: {=ABS(pred_GDP_1qa!T12-pred_GDP_1qa!$B12)} -> 1.945161 | U8: {=ABS(pred_GDP_1qa!U12-pred_GDP_1qa!$B12)} -> 1.9213166 | V8: {=ABS(pred_GDP_1qa!V12-pred_GDP_1qa!$B12)} -> 2.1282521 | W8: {=ABS(pred_GDP_1qa!W12-pred_GDP_1qa!$B12)} -> 2.1239222 | X8: {=ABS(pred_GDP_1qa!X12-pred_GDP_1qa!$B12)} -> 2.1366229 | Y8: {=ABS(pred_GDP_1qa!Y12-pred_GDP_1qa!$B12)} -> 2.506014 | Z8: {=ABS(pred_GDP_1qa!Z12-pred_GDP_1qa!$B12)} -> 1.945161
A9: 40148 | B9: 0.7 | C9: {=ABS(pred_GDP_1qa!C13-pred_GDP_1qa!$B13)} -> #N/A | D9: {=ABS(pred_GDP_1qa!D13-pred_GDP_1qa!$B13)} -> 0.16035022 | E9: {=ABS(pred_GDP_1qa!E13-pred_GDP_1qa!$B13)} -> 1.5387659 | F9: {=ABS(pred_GDP_1qa!F13-pred_GDP_1qa!$B13)} -> #N/A | G9: {=ABS(pred_GDP_1qa!G13-pred_GDP_1qa!$B13)} -> #N/A | H9: {=ABS(pred_GDP_1qa!H13-pred_GDP_1qa!$B13)} -> #N/A | I9: {=ABS(pred_GDP_1qa!I13-pred_GDP_1qa!$B13)} -> #N/A | J9: {=ABS(pred_GDP_1qa!J13-pred_GDP_1qa!$B13)} -> #N/A | ... P9: {=ABS(pred_GDP_1qa!P13-pred_GDP_1qa!$B13)} -> 0.63284192 | R9: {=ABS(pred_GDP_1qa!R13-pred_GDP_1qa!$B13)} -> 0.50222101 | S9: {=ABS(pred_GDP_1qa!S13-pred_GDP_1qa!$B13)} -> 0.56905781 | T9: {=ABS(pred_GDP_1qa!T13-pred_GDP_1qa!$B13)} -> 0.56905781 | U9: {=ABS(pred_GDP_1qa!U13-pred_GDP_1qa!$B13)} -> 0.56905781 | V9: {=ABS(pred_GDP_1qa!V13-pred_GDP_1qa!$B13)} -> 0.46308157 | W9: {=ABS(pred_GDP_1qa!W13-pred_GDP_1qa!$B13)} -> 0.46559448 | X9: {=ABS(pred_GDP_1qa!X13-pred_GDP_1qa!$B13)} -> 0.47916474 | Y9: {=ABS(pred_GDP_1qa!Y13-pred_GDP_1qa!$B13)} -> 0.32222157 | Z9: {=ABS(pred_GDP_1qa!Z13-pred_GDP_1qa!$B13)} -> 0.53107816
A10: 40238 | B10: 2.3 | C10: {=ABS(pred_GDP_1qa!C14-pred_GDP_1qa!$B14)} -> #N/A | D10: {=ABS(pred_GDP_1qa!D14-pred_GDP_1qa!$B14)} -> 0.66075558 | E10: {=ABS(pred_GDP_1qa!E14-pred_GDP_1qa!$B14)} -> 0.35774137 | F10: {=ABS(pred_GDP_1qa!F14-pred_GDP_1qa!$B14)} -> #N/A | G10: {=ABS(pred_GDP_1qa!G14-pred_GDP_1qa!$B14)} -> #N/A | H10: {=ABS(pred_GDP_1qa!H14-pred_GDP_1qa!$B14)} -> #N/A | I10: {=ABS(pred_GDP_1qa!I14-pred_GDP_1qa!$B14)} -> #N/A | J10: {=ABS(pred_GDP_1qa!J14-pred_GDP_1qa!$B14)} -> #N/A | ... P10: {=ABS(pred_GDP_1qa!P14-pred_GDP_1qa!$B14)} -> 2.0913631 | R10: {=ABS(pred_GDP_1qa!R14-pred_GDP_1qa!$B14)} -> 1.0975575 | S10: {=ABS(pred_GDP_1qa!S14-pred_GDP_1qa!$B14)} -> 0.94074161 | T10: {=ABS(pred_GDP_1qa!T14-pred_GDP_1qa!$B14)} -> 0.94074161 | U10: {=ABS(pred_GDP_1qa!U14-pred_GDP_1qa!$B14)} -> 0.94074161 | V10: {=ABS(pred_GDP_1qa!V14-pred_GDP_1qa!$B14)} -> 1.1493013 | W10: {=ABS(pred_GDP_1qa!W14-pred_GDP_1qa!$B14)} -> 1.1477863 | X10: {=ABS(pred_GDP_1qa!X14-pred_GDP_1qa!$B14)} -> 1.1317398 | Y10: {=ABS(pred_GDP_1qa!Y14-pred_GDP_1qa!$B14)} -> 1.1588642 | Z10: {=ABS(pred_GDP_1qa!Z14-pred_GDP_1qa!$B14)} -> 1.0864936
