Workbook

Sheet Plan
A2: 1. 모형별 GDP 예측치 취합
B3: core model : | C3: L-bridge1, L-bridge2, L-copular
B4: bigdata model : | C4: KDFM, LBVAR, TFM
B5: additional : | C5: SVR, XGBoost, CRNN, SARIMA, VAR, Quantile regression
C6: RF
A7: 2. 모형별 특성 조사
B8: ex) mixed freq, real-time(daily) update, 경제구조 반영, CPI 예측 가능, density forecasting, embedded variable selection, etc.
A11: 2. Ensemble 검토
B12: - density forecast :
B13: - dynamic selection based on MSE :
B14: - dynamic selection based on ? :
B15: - fixed (average) :
A17: 3. Target 확장
B18: (1). CPI | C18: 가능한 모델 : | D18: TFM, KDFM, LVBAR
B19: (2). 1q ahead GDP
A21: 4. Visualization
B22: - Kernel Density Estimation for each quarter
B23: - Box plot time series
B24: - Fan chart
A26: 5. Writing
B27: Overleaf: | C27: https://www.overleaf.com/8812339134tbdyxcynsqch

Sheet Reference
A1: Category | B1: Title | C1: Paper links | D1: Year | E1: Journal | F1: Comments
A2: SAM | B2: Short-Term Forecasting of GDP and Inflation in Real-Time : Norges Bank’s System for Averaging Models | C2: https://norges-bank.brage.unit.no/norges-bank-xmlui/handle/11250/2507327 | D2: 2011 | E2: NB Working Paper | F2: GDP, CPI 예측
A3: Ensemble | B3: An ensemble of LSTM neural networks for high-frequency stock market classification | C3: https://onlinelibrary.wiley.com/doi/10.1002/for.2585 | D3: 2022 | E3: J of forecasting
A4: Ensemble | B4: Nowcasting monthly GDP with big data: A model averaging approach | C4: https://rss.onlinelibrary.wiley.com/doi/10.1111/rssa.12645 | D4: 2021 | E4: RSSA
B5: Nonlinear inflation forecasting with recurrent neural networks | C5: https://onlinelibrary.wiley.com/doi/10.1002/for.2901 | D5: 2022 | E5: J of forecasting

Sheet Input vars
B1: Number of Vars | C1: Ntional Account | D1: Foreign | E1: Real | F1: Inflation | G1: Financial | H1: Survey | J1: quarter | K1: month | U1: TFM
A2: KDFM | B2: 35 | C2: GDP, 민소, 건설, 설비, 수출 (SA) 5개 | D2: - | E2: 산업생산, 취업률, 수출입 등 14개 | F2: 코어 CPI, PPI, IPI 등 4개 | G2: - | H2: CSI, ESI, BSI 등 9개 | J2: 5 | K2: 30 | U2: 0ma | V2: 1ma | W2: 2ma | X2: 3ma | Y2: 4ma | Z2: 5ma | AA2: 6ma
A3: LDFM1 | B3: 4 | C3: GDP 1개 | D3: - | E3: 전산업생산, 일평균 수출 2개 | F3: - | G3: - | H3: NSI 1개 | J3: 1 | K3: 3
A4: LDFM2 | B4: 4 | C4: GDP 1개 | D4: - | E4: 전산업생산, 일평균 수출 2개 | F4: - | G4: - | H4: NSI 1개 | J4: 1 | K4: 3
A5: Copular | B5: 4 | C5: GDP 1개 | D5: - | E5: 전산업생산, 일평균 수출 2개 | F5: - | G5: - | H5: NSI 1개 | J5: 1 | K5: 3
A6: LBVAR | B6: 32 | C6: GDP, 민소, 건설, 설비, 수출, 수입 (SA) 6개 | D6: 미국,유로,중국 GDP, OECD 선행지수, PMI, FFR 등 8개 | E6: 동행지수, 산업생산, 통관 수출입, 실업률 등 9개 | F6: 코어 CPI, 주택매매가격지수 등 3개 | G6: KRW, EUR 환율, 회사채3년, KOSPI 등 6개 | H6: - | J6: 9 | K6: 23
A7: TFM | B7: 84 | C7: GDP, 소비, 설비, 건설, 정부, 수출, 수입 (SA, NSA) 14개 | D7: - | E7: 통계청 산업생산(소매판매지수, 설비판매지수, ...) | F7: CPI, PPI, IPI, EPI 등 | G7: 콜, KRW, EUR, 유가, KOSPI 등 | H7: CSI, ESI, BSI, NSI 등 9개
A8: TEXT | B8: 31 | C8: GDP, 민소, 설비, 건설, 정부, 수출, 수입 (SA, NSA) 14개 | D8: - | E8: - | F8: - | G8: - | H8: NSI, EPU, TFI 등 17개 | J8: 14 | K8: 17
A9: SVR | B9: 9 | C9: - | D9: - | E9: 전산업생산, 실업률, 수출 등 6개 | F9: - | G9: KRW 환율, 유가, KOSPI 3개 | H9: -
A10: XGBoost | B10: 13 | C10: - | D10: - | E10: - | F10: - | G10: - | H10: CSI, ESI, BSI, NSI 등 13개
A11: RF | B11: 144 | C11: - | D11: 미국, 독일, 일본 GDP, OECD 선행지수 등 12개 | E11: 전산업생산, 실업률, 수출 등 73개 | F11: CPI, PPI, 주택매매가격지수 등 7개 | G11: 통화량, KRW 환율, 유가, KOSPI 등 33개 | H11: CSI, ESI, BSI, NSI 등 19개

Sheet Any comments
A2: 5.18. SBS : 그래프 참고
A12: 5.18 SBS : Target을 고용, 금융 surveilance 등으로 확대하면 좋을듯

Sheet pred_Ens_now
B1: GDP(SA) True | C1: Min | D1: Max | E1: Avg | F1: Median | G1: Med_item | H1: Adaptive selection | I1: Min1y_item | J1: Adaptive selection 1y | K1: Adaptive top5 1y | L1: Adaptive top3 1y | N1: 10percentile | O1: 25percentile | P1: median | Q1: 75percentile | R1: 90percentile
A2: 201603 | B2: 0.3 | C2: =min(pred_GDP_now!$C2:$Z2) -> -0.28277946 | D2: =MAX(pred_GDP_now!$C2:$Z2) -> 0.81979479 | E2: =AVERAGE(pred_GDP_now!$C2:$Z2) -> 0.35540903 | F2: =MEDIAN(pred_GDP_now!$C2:$Z2) -> 0.3269035 | N2: =percentile(pred_GDP_now!$C2:$Z2,0.1) -> 0.0562622 | O2: =percentile(pred_GDP_now!$C2:$Z2,0.25) -> 0.12235838 | P2: =percentile(pred_GDP_now!$C2:$Z2,0.5) -> 0.3269035 | Q2: =percentile(pred_GDP_now!$C2:$Z2,0.75) -> 0.56274242 | R2: =percentile(pred_GDP_now!$C2:$Z2,0.9) -> 0.7828439 | S2: =R2-N2 -> 0.7265817 | T2: =Q2-O2 -> 0.44038404
A3: 201606 | B3: 1.2 | C3: =min(pred_GDP_now!$C3:$Z3) -> 0.351429 | D3: =MAX(pred_GDP_now!$C3:$Z3) -> 1.7542191 | E3: =AVERAGE(pred_GDP_now!$C3:$Z3) -> 0.93919909 | F3: =MEDIAN(pred_GDP_now!$C3:$Z3) -> 0.90087982 | G3: {=index(pred_GDP_now!$C$1:$Z$1,1,match(MEDIAN(pred_GDP_now!$C2:$Z2),pred_GDP_now!$C2:$Z2))} -> BEM3 | H3: {=index(pred_GDP_now!$C3:$Z3,1,match(F2,pred_GDP_now!$C2:$Z2))} -> 0.891963 | N3: =percentile(pred_GDP_now!$C3:$Z3,0.1) -> 0.56936044 | O3: =percentile(pred_GDP_now!$C3:$Z3,0.25) -> 0.79155211 | P3: =percentile(pred_GDP_now!$C3:$Z3,0.5) -> 0.90087982 | Q3: =percentile(pred_GDP_now!$C3:$Z3,0.75) -> 1.0673239 | R3: =percentile(pred_GDP_now!$C3:$Z3,0.9) -> 1.2264864 | S3: =R3-N3 -> 0.65712596 | T3: =Q3-O3 -> 0.27577181
A4: 201609 | B4: 0.4 | C4: =min(pred_GDP_now!$C4:$Z4) -> 0.442873 | D4: =MAX(pred_GDP_now!$C4:$Z4) -> 0.95351116 | E4: =AVERAGE(pred_GDP_now!$C4:$Z4) -> 0.71328302 | F4: =MEDIAN(pred_GDP_now!$C4:$Z4) -> 0.69082605 | G4: {=index(pred_GDP_now!$C$1:$Z$1,1,match(MEDIAN(pred_GDP_now!$C3:$Z3),pred_GDP_now!$C3:$Z3))} -> LBVAR | H4: {=index(pred_GDP_now!$C4:$Z4,1,match(F3,pred_GDP_now!$C3:$Z3))} -> 0.936626 | N4: =percentile(pred_GDP_now!$C4:$Z4,0.1) -> 0.48284465 | O4: =percentile(pred_GDP_now!$C4:$Z4,0.25) -> 0.57108425 | P4: =percentile(pred_GDP_now!$C4:$Z4,0.5) -> 0.69082605 | Q4: =percentile(pred_GDP_now!$C4:$Z4,0.75) -> 0.91213058 | R4: =percentile(pred_GDP_now!$C4:$Z4,0.9) -> 0.9460599 | S4: =R4-N4 -> 0.46321525 | T4: =Q4-O4 -> 0.34104633
A5: 201612 | B5: 0.6 | C5: =min(pred_GDP_now!$C5:$Z5) -> 0.575754 | D5: =MAX(pred_GDP_now!$C5:$Z5) -> 1.336816 | E5: =AVERAGE(pred_GDP_now!$C5:$Z5) -> 0.92340418 | F5: =MEDIAN(pred_GDP_now!$C5:$Z5) -> 0.91673305 | G5: {=index(pred_GDP_now!$C$1:$Z$1,1,match(MEDIAN(pred_GDP_now!$C4:$Z4),pred_GDP_now!$C4:$Z4))} -> BEM3 | H5: {=index(pred_GDP_now!$C5:$Z5,1,match(F4,pred_GDP_now!$C4:$Z4))} -> 0.712063 | N5: =percentile(pred_GDP_now!$C5:$Z5,0.1) -> 0.6579339 | O5: =percentile(pred_GDP_now!$C5:$Z5,0.25) -> 0.71770891 | P5: =percentile(pred_GDP_now!$C5:$Z5,0.5) -> 0.91673305 | Q5: =percentile(pred_GDP_now!$C5:$Z5,0.75) -> 1.091472 | R5: =percentile(pred_GDP_now!$C5:$Z5,0.9) -> 1.2384428 | S5: =R5-N5 -> 0.58050886 | T5: =Q5-O5 -> 0.37376312
A6: 201703 | B6: 1 | C6: =min(pred_GDP_now!$C6:$Z6) -> 0.647591 | D6: =MAX(pred_GDP_now!$C6:$Z6) -> 1.447208 | E6: =AVERAGE(pred_GDP_now!$C6:$Z6) -> 1.0554523 | F6: =MEDIAN(pred_GDP_now!$C6:$Z6) -> 1.0756661 | G6: {=index(pred_GDP_now!$C$1:$Z$1,1,match(MEDIAN(pred_GDP_now!$C5:$Z5),pred_GDP_now!$C5:$Z5))} -> LBVAR | H6: {=index(pred_GDP_now!$C6:$Z6,1,match(F5,pred_GDP_now!$C5:$Z5))} -> 0.647591 | N6: =percentile(pred_GDP_now!$C6:$Z6,0.1) -> 0.84079291 | O6: =percentile(pred_GDP_now!$C6:$Z6,0.25) -> 1.049543 | P6: =percentile(pred_GDP_now!$C6:$Z6,0.5) -> 1.0756661 | Q6: =percentile(pred_GDP_now!$C6:$Z6,0.75) -> 1.1112154 | R6: =percentile(pred_GDP_now!$C6:$Z6,0.9) -> 1.1854212 | S6: =R6-N6 -> 0.34462825 | T6: =Q6-O6 -> 0.061672334
A7: 201706 | B7: 0.8 | C7: =min(pred_GDP_now!$C7:$Z7) -> 0.50836078 | D7: =MAX(pred_GDP_now!$C7:$Z7) -> 1.284572 | E7: =AVERAGE(pred_GDP_now!$C7:$Z7) -> 0.93931501 | F7: =MEDIAN(pred_GDP_now!$C7:$Z7) -> 0.94514546 | G7: {=index(pred_GDP_now!$C$1:$Z$1,1,match(MEDIAN(pred_GDP_now!$C6:$Z6),pred_GDP_now!$C6:$Z6))} -> T-M | H7: {=index(pred_GDP_now!$C7:$Z7,1,match(F6,pred_GDP_now!$C6:$Z6))} -> 0.94488392 | I7: {=index(pred_GDP_now!$C$1:$Z$1,1,match(min('Ens_now작업'!$C6:$Z6),'Ens_now작업'!$C6:$Z6,0))} -> BEM1 | J7: {=index(pred_GDP_now!$C7:$Z7,1,match(min('Ens_now작업'!$C6:$Z6),'Ens_now작업'!$C6:$Z6,0))} -> 1.108525 | K7: =AVERAGE('Ens_now작업2'!$C7:$Z7) -> 1.0449862 | L7: =AVERAGE('Ens_now작업3'!$C7:$Z7) -> 1.083297 | N7: =percentile(pred_GDP_now!$C7:$Z7,0.1) -> 0.7185911 | O7: =percentile(pred_GDP_now!$C7:$Z7,0.25) -> 0.79299871 | P7: =percentile(pred_GDP_now!$C7:$Z7,0.5) -> 0.94514546 | Q7: =percentile(pred_GDP_now!$C7:$Z7,0.75) -> 1.088802 | R7: =percentile(pred_GDP_now!$C7:$Z7,0.9) -> 1.1719437 | S7: =R7-N7 -> 0.45335257 | T7: =Q7-O7 -> 0.29580325
A8: 201709 | B8: 1.4 | C8: =min(pred_GDP_now!$C8:$Z8) -> 0.275753 | D8: =MAX(pred_GDP_now!$C8:$Z8) -> 0.973802 | E8: =AVERAGE(pred_GDP_now!$C8:$Z8) -> 0.72659198 | F8: =MEDIAN(pred_GDP_now!$C8:$Z8) -> 0.77195513 | G8: {=index(pred_GDP_now!$C$1:$Z$1,1,match(MEDIAN(pred_GDP_now!$C7:$Z7),pred_GDP_now!$C7:$Z7))} -> RF-DVS | H8: {=index(pred_GDP_now!$C8:$Z8,1,match(F7,pred_GDP_now!$C7:$Z7))} -> 0.8004513 | I8: {=index(pred_GDP_now!$C$1:$Z$1,1,match(min('Ens_now작업'!$C7:$Z7),'Ens_now작업'!$C7:$Z7,0))} -> BEM2 | J8: {=index(pred_GDP_now!$C8:$Z8,1,match(min('Ens_now작업'!$C7:$Z7),'Ens_now작업'!$C7:$Z7,0))} -> 0.275753 | K8: =AVERAGE('Ens_now작업2'!$C8:$Z8) -> 0.54375144 | L8: =AVERAGE('Ens_now작업3'!$C8:$Z8) -> 0.32089833 | N8: =percentile(pred_GDP_now!$C8:$Z8,0.1) -> 0.321163 | O8: =percentile(pred_GDP_now!$C8:$Z8,0.25) -> 0.68502043 | P8: =percentile(pred_GDP_now!$C8:$Z8,0.5) -> 0.77195513 | Q8: =percentile(pred_GDP_now!$C8:$Z8,0.75) -> 0.91098794 | R8: =percentile(pred_GDP_now!$C8:$Z8,0.9) -> 0.9667883 | S8: =R8-N8 -> 0.6456253 | T8: =Q8-O8 -> 0.22596751
A9: 201712 | B9: -0.3 | C9: =min(pred_GDP_now!$C9:$Z9) -> 0.354928 | D9: =MAX(pred_GDP_now!$C9:$Z9) -> 1.387553 | E9: =AVERAGE(pred_GDP_now!$C9:$Z9) -> 0.76334476 | F9: =MEDIAN(pred_GDP_now!$C9:$Z9) -> 0.73130219 | G9: {=index(pred_GDP_now!$C$1:$Z$1,1,match(MEDIAN(pred_GDP_now!$C8:$Z8),pred_GDP_now!$C8:$Z8))} -> BEM3 | H9: {=index(pred_GDP_now!$C9:$Z9,1,match(F8,pred_GDP_now!$C8:$Z8))} -> 0.895778 | I9: {=index(pred_GDP_now!$C$1:$Z$1,1,match(min('Ens_now작업'!$C8:$Z8),'Ens_now작업'!$C8:$Z8,0))} -> LQR | J9: {=index(pred_GDP_now!$C9:$Z9,1,match(min('Ens_now작업'!$C8:$Z8),'Ens_now작업'!$C8:$Z8,0))} -> 0.354928 | K9: =AVERAGE('Ens_now작업2'!$C9:$Z9) -> 0.72402163 | L9: =AVERAGE('Ens_now작업3'!$C9:$Z9) -> 0.64149233 | N9: =percentile(pred_GDP_now!$C9:$Z9,0.1) -> 0.48852739 | O9: =percentile(pred_GDP_now!$C9:$Z9,0.25) -> 0.678852 | P9: =percentile(pred_GDP_now!$C9:$Z9,0.5) -> 0.73130219 | Q9: =percentile(pred_GDP_now!$C9:$Z9,0.75) -> 0.88865022 | R9: =percentile(pred_GDP_now!$C9:$Z9,0.9) -> 0.9353987 | S9: =R9-N9 -> 0.44687131 | T9: =Q9-O9 -> 0.20979822
A10: 201803 | B10: 1.3 | C10: =min(pred_GDP_now!$C10:$Z10) -> 0.678722 | D10: =MAX(pred_GDP_now!$C10:$Z10) -> 1.71661 | E10: =AVERAGE(pred_GDP_now!$C10:$Z10) -> 0.94867323 | F10: =MEDIAN(pred_GDP_now!$C10:$Z10) -> 0.8725805 | G10: {=index(pred_GDP_now!$C$1:$Z$1,1,match(MEDIAN(pred_GDP_now!$C9:$Z9),pred_GDP_now!$C9:$Z9))} -> CRNN | H10: {=index(pred_GDP_now!$C10:$Z10,1,match(F9,pred_GDP_now!$C9:$Z9))} -> 0.80441034 | I10: {=index(pred_GDP_now!$C$1:$Z$1,1,match(min('Ens_now작업'!$C9:$Z9),'Ens_now작업'!$C9:$Z9,0))} -> LBVAR | J10: {=index(pred_GDP_now!$C10:$Z10,1,match(min('Ens_now작업'!$C9:$Z9),'Ens_now작업'!$C9:$Z9,0))} -> 0.753485 | K10: =AVERAGE('Ens_now작업2'!$C10:$Z10) -> 0.91041805 | L10: =AVERAGE('Ens_now작업3'!$C10:$Z10) -> 0.93411009 | N10: =percentile(pred_GDP_now!$C10:$Z10,0.1) -> 0.71044038 | O10: =percentile(pred_GDP_now!$C10:$Z10,0.25) -> 0.74661275 | P10: =percentile(pred_GDP_now!$C10:$Z10,0.5) -> 0.8725805 | Q10: =percentile(pred_GDP_now!$C10:$Z10,0.75) -> 1.0823579 | R10: =percentile(pred_GDP_now!$C10:$Z10,0.9) -> 1.1833963 | S10: =R10-N10 -> 0.47295592 | T10: =Q10-O10 -> 0.33574512
A11: 201806 | B11: 0.7 | C11: =min(pred_GDP_now!$C11:$Z11) -> 0.31626 | D11: =MAX(pred_GDP_now!$C11:$Z11) -> 1.3132168 | E11: =AVERAGE(pred_GDP_now!$C11:$Z11) -> 0.67872928 | F11: =MEDIAN(pred_GDP_now!$C11:$Z11) -> 0.61506395 | G11: {=index(pred_GDP_now!$C$1:$Z$1,1,match(MEDIAN(pred_GDP_now!$C10:$Z10),pred_GDP_now!$C10:$Z10))} -> LBVAR | H11: {=index(pred_GDP_now!$C11:$Z11,1,match(F10,pred_GDP_now!$C10:$Z10))} -> 0.31626 | I11: {=index(pred_GDP_now!$C$1:$Z$1,1,match(min('Ens_now작업'!$C10:$Z10),'Ens_now작업'!$C10:$Z10,0))} -> VAR | J11: {=index(pred_GDP_now!$C11:$Z11,1,match(min('Ens_now작업'!$C10:$Z10),'Ens_now작업'!$C10:$Z10,0))} -> 0.837201 | K11: =AVERAGE('Ens_now작업2'!$C11:$Z11) -> 0.63025017 | L11: =AVERAGE('Ens_now작업3'!$C11:$Z11) -> 0.70078742 | N11: =percentile(pred_GDP_now!$C11:$Z11,0.1) -> 0.51464993 | O11: =percentile(pred_GDP_now!$C11:$Z11,0.25) -> 0.55594987 | P11: =percentile(pred_GDP_now!$C11:$Z11,0.5) -> 0.61506395 | Q11: =percentile(pred_GDP_now!$C11:$Z11,0.75) -> 0.70882925 | R11: =percentile(pred_GDP_now!$C11:$Z11,0.9) -> 0.92287739 | S11: =R11-N11 -> 0.40822746 | T11: =Q11-O11 -> 0.15287938
A12: 201809 | B12: 0.6 | C12: =min(pred_GDP_now!$C12:$Z12) -> 0.320519 | D12: =MAX(pred_GDP_now!$C12:$Z12) -> 1.0800163 | E12: =AVERAGE(pred_GDP_now!$C12:$Z12) -> 0.63921067 | F12: =MEDIAN(pred_GDP_now!$C12:$Z12) -> 0.59250633 | G12: {=index(pred_GDP_now!$C$1:$Z$1,1,match(MEDIAN(pred_GDP_now!$C11:$Z11),pred_GDP_now!$C11:$Z11))} -> T-M | H12: {=index(pred_GDP_now!$C12:$Z12,1,match(F11,pred_GDP_now!$C11:$Z11))} -> 1.0457688 | I12: {=index(pred_GDP_now!$C$1:$Z$1,1,match(min('Ens_now작업'!$C11:$Z11),'Ens_now작업'!$C11:$Z11,0))} -> SVR-KNN | J12: {=index(pred_GDP_now!$C12:$Z12,1,match(min('Ens_now작업'!$C11:$Z11),'Ens_now작업'!$C11:$Z11,0))} -> 0.60425636 | K12: =AVERAGE('Ens_now작업2'!$C12:$Z12) -> 0.70742781 | L12: =AVERAGE('Ens_now작업3'!$C12:$Z12) -> 0.62894289 | N12: =percentile(pred_GDP_now!$C12:$Z12,0.1) -> 0.35177845 | O12: =percentile(pred_GDP_now!$C12:$Z12,0.25) -> 0.4876715 | P12: =percentile(pred_GDP_now!$C12:$Z12,0.5) -> 0.59250633 | Q12: =percentile(pred_GDP_now!$C12:$Z12,0.75) -> 0.69772634 | R12: =percentile(pred_GDP_now!$C12:$Z12,0.9) -> 1.0233674 | S12: =R12-N12 -> 0.67158892 | T12: =Q12-O12 -> 0.21005484
A13: 201812 | B13: 0.6 | C13: =min(pred_GDP_now!$C13:$Z13) -> -0.02169 | D13: =MAX(pred_GDP_now!$C13:$Z13) -> 1.1399713 | E13: =AVERAGE(pred_GDP_now!$C13:$Z13) -> 0.42536069 | F13: =MEDIAN(pred_GDP_now!$C13:$Z13) -> 0.38088987 | G13: {=index(pred_GDP_now!$C$1:$Z$1,1,match(MEDIAN(pred_GDP_now!$C12:$Z12),pred_GDP_now!$C12:$Z12))} -> LBVAR | H13: {=index(pred_GDP_now!$C13:$Z13,1,match(F12,pred_GDP_now!$C12:$Z12))} -> 0.749574 | I13: {=index(pred_GDP_now!$C$1:$Z$1,1,match(min('Ens_now작업'!$C12:$Z12),'Ens_now작업'!$C12:$Z12,0))} -> SVR-KNN | J13: {=index(pred_GDP_now!$C13:$Z13,1,match(min('Ens_now작업'!$C12:$Z12),'Ens_now작업'!$C12:$Z12,0))} -> 0.45311828 | K13: =AVERAGE('Ens_now작업2'!$C13:$Z13) -> 0.53594862 | L13: =AVERAGE('Ens_now작업3'!$C13:$Z13) -> 0.42462676 | N13: =percentile(pred_GDP_now!$C13:$Z13,0.1) -> 0.068340909 | O13: =percentile(pred_GDP_now!$C13:$Z13,0.25) -> 0.1497315 | P13: =percentile(pred_GDP_now!$C13:$Z13,0.5) -> 0.38088987 | Q13: =percentile(pred_GDP_now!$C13:$Z13,0.75) -> 0.69262376 | R13: =percentile(pred_GDP_now!$C13:$Z13,0.9) -> 0.74234688 | S13: =R13-N13 -> 0.67400597 | T13: =Q13-O13 -> 0.54289226
A14: 201903 | B14: -0.1 | C14: =min(pred_GDP_now!$C14:$Z14) -> -0.567977 | D14: =MAX(pred_GDP_now!$C14:$Z14) -> 0.75638 | E14: =AVERAGE(pred_GDP_now!$C14:$Z14) -> 0.23252975 | F14: =MEDIAN(pred_GDP_now!$C14:$Z14) -> 0.259024 | G14: {=index(pred_GDP_now!$C$1:$Z$1,1,match(MEDIAN(pred_GDP_now!$C13:$Z13),pred_GDP_now!$C13:$Z13))} -> BEM3 | H14: {=index(pred_GDP_now!$C14:$Z14,1,match(F13,pred_GDP_now!$C13:$Z13))} -> 0.156505 | I14: {=index(pred_GDP_now!$C$1:$Z$1,1,match(min('Ens_now작업'!$C13:$Z13),'Ens_now작업'!$C13:$Z13,0))} -> SVR-KNN | J14: {=index(pred_GDP_now!$C14:$Z14,1,match(min('Ens_now작업'!$C13:$Z13),'Ens_now작업'!$C13:$Z13,0))} -> -0.086190051 | K14: =AVERAGE('Ens_now작업2'!$C14:$Z14) -> 5.2374093e-05 | L14: =AVERAGE('Ens_now작업3'!$C14:$Z14) -> -0.013610377 | N14: =percentile(pred_GDP_now!$C14:$Z14,0.1) -> -0.290057 | O14: =percentile(pred_GDP_now!$C14:$Z14,0.25) -> -0.082707538 | P14: =percentile(pred_GDP_now!$C14:$Z14,0.5) -> 0.259024 | Q14: =percentile(pred_GDP_now!$C14:$Z14,0.75) -> 0.6115525 | R14: =percentile(pred_GDP_now!$C14:$Z14,0.9) -> 0.70336703 | S14: =R14-N14 -> 0.99342403 | T14: =Q14-O14 -> 0.69426003
A15: 201906 | B15: 1.1 | C15: =min(pred_GDP_now!$C15:$Z15) -> 0.5128888 | D15: =MAX(pred_GDP_now!$C15:$Z15) -> 1.3090551 | E15: =AVERAGE(pred_GDP_now!$C15:$Z15) -> 0.95556426 | F15: =MEDIAN(pred_GDP_now!$C15:$Z15) -> 0.9269905 | G15: {=index(pred_GDP_now!$C$1:$Z$1,1,match(MEDIAN(pred_GDP_now!$C14:$Z14),pred_GDP_now!$C14:$Z14))} -> BEM3 | H15: {=index(pred_GDP_now!$C15:$Z15,1,match(F14,pred_GDP_now!$C14:$Z14))} -> 0.803238 | I15: {=index(pred_GDP_now!$C$1:$Z$1,1,match(min('Ens_now작업'!$C14:$Z14),'Ens_now작업'!$C14:$Z14,0))} -> SVR-KNN | J15: {=index(pred_GDP_now!$C15:$Z15,1,match(min('Ens_now작업'!$C14:$Z14),'Ens_now작업'!$C14:$Z14,0))} -> 0.87297946 | K15: =AVERAGE('Ens_now작업2'!$C15:$Z15) -> 0.88363496 | L15: =AVERAGE('Ens_now작업3'!$C15:$Z15) -> 0.87291812 | N15: =percentile(pred_GDP_now!$C15:$Z15,0.1) -> 0.8135292 | O15: =percentile(pred_GDP_now!$C15:$Z15,0.25) -> 0.85675973 | P15: =percentile(pred_GDP_now!$C15:$Z15,0.5) -> 0.9269905 | Q15: =percentile(pred_GDP_now!$C15:$Z15,0.75) -> 1.0600314 | R15: =percentile(pred_GDP_now!$C15:$Z15,0.9) -> 1.2118837 | S15: =R15-N15 -> 0.39835451 | T15: =Q15-O15 -> 0.20327167
A16: 201909 | B16: 0.4 | C16: =min(pred_GDP_now!$C16:$Z16) -> 0.351543 | D16: =MAX(pred_GDP_now!$C16:$Z16) -> 1.1893855 | E16: =AVERAGE(pred_GDP_now!$C16:$Z16) -> 0.7006273 | F16: =MEDIAN(pred_GDP_now!$C16:$Z16) -> 0.69009547 | G16: {=index(pred_GDP_now!$C$1:$Z$1,1,match(MEDIAN(pred_GDP_now!$C15:$Z15),pred_GDP_now!$C15:$Z15))} -> RF-DVS | H16: {=index(pred_GDP_now!$C16:$Z16,1,match(F15,pred_GDP_now!$C15:$Z15))} -> 0.70446534 | I16: {=index(pred_GDP_now!$C$1:$Z$1,1,match(min('Ens_now작업'!$C15:$Z15),'Ens_now작업'!$C15:$Z15,0))} -> SVR-KNN | J16: {=index(pred_GDP_now!$C16:$Z16,1,match(min('Ens_now작업'!$C15:$Z15),'Ens_now작업'!$C15:$Z15,0))} -> 0.47015826 | K16: =AVERAGE('Ens_now작업2'!$C16:$Z16) -> 0.58390685 | L16: =AVERAGE('Ens_now작업3'!$C16:$Z16) -> 0.47714375 | N16: =percentile(pred_GDP_now!$C16:$Z16,0.1) -> 0.45591448 | O16: =percentile(pred_GDP_now!$C16:$Z16,0.25) -> 0.48702159 | P16: =percentile(pred_GDP_now!$C16:$Z16,0.5) -> 0.69009547 | Q16: =percentile(pred_GDP_now!$C16:$Z16,0.75) -> 0.80229175 | R16: =percentile(pred_GDP_now!$C16:$Z16,0.9) -> 1.0104611 | S16: =R16-N16 -> 0.55454663 | T16: =Q16-O16 -> 0.31527016
A17: 201912 | B17: 1.2 | C17: =min(pred_GDP_now!$C17:$Z17) -> 0.077020831 | D17: =MAX(pred_GDP_now!$C17:$Z17) -> 1.1246174 | E17: =AVERAGE(pred_GDP_now!$C17:$Z17) -> 0.67144946 | F17: =MEDIAN(pred_GDP_now!$C17:$Z17) -> 0.66286925 | G17: {=index(pred_GDP_now!$C$1:$Z$1,1,match(MEDIAN(pred_GDP_now!$C16:$Z16),pred_GDP_now!$C16:$Z16))} -> SVR-KNN | H17: {=index(pred_GDP_now!$C17:$Z17,1,match(F16,pred_GDP_now!$C16:$Z16))} -> 0.8978016 | I17: {=index(pred_GDP_now!$C$1:$Z$1,1,match(min('Ens_now작업'!$C16:$Z16),'Ens_now작업'!$C16:$Z16,0))} -> SVR-KNN | J17: {=index(pred_GDP_now!$C17:$Z17,1,match(min('Ens_now작업'!$C16:$Z16),'Ens_now작업'!$C16:$Z16,0))} -> 0.8978016 | K17: =AVERAGE('Ens_now작업2'!$C17:$Z17) -> 0.71405782 | L17: =AVERAGE('Ens_now작업3'!$C17:$Z17) -> 0.79029287 | N17: =percentile(pred_GDP_now!$C17:$Z17,0.1) -> 0.3119385 | O17: =percentile(pred_GDP_now!$C17:$Z17,0.25) -> 0.55998388 | P17: =percentile(pred_GDP_now!$C17:$Z17,0.5) -> 0.66286925 | Q17: =percentile(pred_GDP_now!$C17:$Z17,0.75) -> 0.87213219 | R17: =percentile(pred_GDP_now!$C17:$Z17,0.9) -> 0.95221028 | S17: =R17-N17 -> 0.64027178 | T17: =Q17-O17 -> 0.31214831
A18: 202003 | B18: -1.3 | C18: =min(pred_GDP_now!$C18:$Z18) -> -0.72131866 | D18: =MAX(pred_GDP_now!$C18:$Z18) -> 0.839619 | E18: =AVERAGE(pred_GDP_now!$C18:$Z18) -> 0.11210531 | F18: =MEDIAN(pred_GDP_now!$C18:$Z18) -> 0.045004424 | G18: {=index(pred_GDP_now!$C$1:$Z$1,1,match(MEDIAN(pred_GDP_now!$C17:$Z17),pred_GDP_now!$C17:$Z17))} -> LBVAR | H18: {=index(pred_GDP_now!$C18:$Z18,1,match(F17,pred_GDP_now!$C17:$Z17))} -> 0.279367 | I18: {=index(pred_GDP_now!$C$1:$Z$1,1,match(min('Ens_now작업'!$C17:$Z17),'Ens_now작업'!$C17:$Z17,0))} -> SVR-KNN | J18: {=index(pred_GDP_now!$C18:$Z18,1,match(min('Ens_now작업'!$C17:$Z17),'Ens_now작업'!$C17:$Z17,0))} -> 0.23187381 | K18: =AVERAGE('Ens_now작업2'!$C18:$Z18) -> 0.066377582 | L18: =AVERAGE('Ens_now작업3'!$C18:$Z18) -> 0.062578354 | N18: =percentile(pred_GDP_now!$C18:$Z18,0.1) -> -0.11444362 | O18: =percentile(pred_GDP_now!$C18:$Z18,0.25) -> -0.033963863 | P18: =percentile(pred_GDP_now!$C18:$Z18,0.5) -> 0.045004424 | Q18: =percentile(pred_GDP_now!$C18:$Z18,0.75) -> 0.2674937 | R18: =percentile(pred_GDP_now!$C18:$Z18,0.9) -> 0.52694462 | S18: =R18-N18 -> 0.64138824 | T18: =Q18-O18 -> 0.30145756
... A30: 202303 | B30: 0.3 | C30: =min(pred_GDP_now!$C30:$Z30) -> 0.056324366 | D30: =MAX(pred_GDP_now!$C30:$Z30) -> 0.606136 | E30: =AVERAGE(pred_GDP_now!$C30:$Z30) -> 0.37668744 | F30: =MEDIAN(pred_GDP_now!$C30:$Z30) -> 0.426876 | G30: {=index(pred_GDP_now!$C$1:$Z$1,1,match(MEDIAN(pred_GDP_now!$C29:$Z29),pred_GDP_now!$C29:$Z29))} -> CRNN | H30: {=index(pred_GDP_now!$C30:$Z30,1,match(F29,pred_GDP_now!$C29:$Z29))} | I30: {=index(pred_GDP_now!$C$1:$Z$1,1,match(min('Ens_now작업'!$C29:$Z29),'Ens_now작업'!$C29:$Z29,0))} -> BEM1 | J30: {=index(pred_GDP_now!$C30:$Z30,1,match(min('Ens_now작업'!$C29:$Z29),'Ens_now작업'!$C29:$Z29,0))} -> 0.32618 | K30: =AVERAGE('Ens_now작업2'!$C30:$Z30) -> 0.34965291 | L30: =AVERAGE('Ens_now작업3'!$C30:$Z30) -> 0.32391188 | N30: =percentile(pred_GDP_now!$C30:$Z30,0.1) -> 0.16389607 | O30: =percentile(pred_GDP_now!$C30:$Z30,0.25) -> 0.32618 | P30: =percentile(pred_GDP_now!$C30:$Z30,0.5) -> 0.426876 | Q30: =percentile(pred_GDP_now!$C30:$Z30,0.75) -> 0.45476664 | R30: =percentile(pred_GDP_now!$C30:$Z30,0.9) -> 0.53339878 | S30: =R30-N30 -> 0.3695027 | T30: =Q30-O30 -> 0.12858664

Sheet err_Ens_now
B1: GDP(SA) True | C1: Min | D1: Max | E1: Avg | F1: Median | H1: Adaptive selection | J1: Adaptive selection 1y | K1: Adaptive top5 1y | L1: Adaptive top5 1y
A2: 201603 | B2: 0.3 | C2: =abs(pred_Ens_now!C2-pred_Ens_now!$B2) -> 0.58277946 | D2: =abs(pred_Ens_now!D2-pred_Ens_now!$B2) -> 0.51979479 | E2: =abs(pred_Ens_now!E2-pred_Ens_now!$B2) -> 0.055409029 | F2: =abs(pred_Ens_now!F2-pred_Ens_now!$B2) -> 0.026903497
A3: 201606 | B3: 1.2 | C3: =abs(pred_Ens_now!C3-pred_Ens_now!$B3) -> 0.848571 | D3: =abs(pred_Ens_now!D3-pred_Ens_now!$B3) -> 0.55421906 | E3: =abs(pred_Ens_now!E3-pred_Ens_now!$B3) -> 0.26080091 | F3: =abs(pred_Ens_now!F3-pred_Ens_now!$B3) -> 0.29912018
A4: 201609 | B4: 0.4 | C4: =abs(pred_Ens_now!C4-pred_Ens_now!$B4) -> 0.042873 | D4: =abs(pred_Ens_now!D4-pred_Ens_now!$B4) -> 0.55351116 | E4: =abs(pred_Ens_now!E4-pred_Ens_now!$B4) -> 0.31328302 | F4: =abs(pred_Ens_now!F4-pred_Ens_now!$B4) -> 0.29082605
A5: 201612 | B5: 0.6 | C5: =abs(pred_Ens_now!C5-pred_Ens_now!$B5) -> 0.024246 | D5: =abs(pred_Ens_now!D5-pred_Ens_now!$B5) -> 0.736816 | E5: =abs(pred_Ens_now!E5-pred_Ens_now!$B5) -> 0.32340418 | F5: =abs(pred_Ens_now!F5-pred_Ens_now!$B5) -> 0.31673305
A6: 201703 | B6: 1 | C6: =abs(pred_Ens_now!C6-pred_Ens_now!$B6) -> 0.352409 | D6: =abs(pred_Ens_now!D6-pred_Ens_now!$B6) -> 0.447208 | E6: =abs(pred_Ens_now!E6-pred_Ens_now!$B6) -> 0.055452283 | F6: =abs(pred_Ens_now!F6-pred_Ens_now!$B6) -> 0.075666118
A7: 201706 | B7: 0.8 | C7: =abs(pred_Ens_now!C7-pred_Ens_now!$B7) -> 0.29163922 | D7: =abs(pred_Ens_now!D7-pred_Ens_now!$B7) -> 0.484572 | E7: =abs(pred_Ens_now!E7-pred_Ens_now!$B7) -> 0.13931501 | F7: =abs(pred_Ens_now!F7-pred_Ens_now!$B7) -> 0.14514546 | H7: =abs(pred_Ens_now!H7-pred_Ens_now!$B7) -> 0.14488392 | J7: =abs(pred_Ens_now!J7-pred_Ens_now!$B7) -> 0.308525 | K7: =abs(pred_Ens_now!K7-pred_Ens_now!$B7) -> 0.24498617 | L7: =abs(pred_Ens_now!L7-pred_Ens_now!$B7) -> 0.283297
A8: 201709 | B8: 1.4 | C8: =abs(pred_Ens_now!C8-pred_Ens_now!$B8) -> 1.124247 | D8: =abs(pred_Ens_now!D8-pred_Ens_now!$B8) -> 0.426198 | E8: =abs(pred_Ens_now!E8-pred_Ens_now!$B8) -> 0.67340802 | F8: =abs(pred_Ens_now!F8-pred_Ens_now!$B8) -> 0.62804487 | H8: =abs(pred_Ens_now!H8-pred_Ens_now!$B8) -> 0.5995487 | J8: =abs(pred_Ens_now!J8-pred_Ens_now!$B8) -> 1.124247 | K8: =abs(pred_Ens_now!K8-pred_Ens_now!$B8) -> 0.85624856 | L8: =abs(pred_Ens_now!L8-pred_Ens_now!$B8) -> 1.0791017
A9: 201712 | B9: -0.3 | C9: =abs(pred_Ens_now!C9-pred_Ens_now!$B9) -> 0.654928 | D9: =abs(pred_Ens_now!D9-pred_Ens_now!$B9) -> 1.687553 | E9: =abs(pred_Ens_now!E9-pred_Ens_now!$B9) -> 1.0633448 | F9: =abs(pred_Ens_now!F9-pred_Ens_now!$B9) -> 1.0313022 | H9: =abs(pred_Ens_now!H9-pred_Ens_now!$B9) -> 1.195778 | J9: =abs(pred_Ens_now!J9-pred_Ens_now!$B9) -> 0.654928 | K9: =abs(pred_Ens_now!K9-pred_Ens_now!$B9) -> 1.0240216 | L9: =abs(pred_Ens_now!L9-pred_Ens_now!$B9) -> 0.94149233
A10: 201803 | B10: 1.3 | C10: =abs(pred_Ens_now!C10-pred_Ens_now!$B10) -> 0.621278 | D10: =abs(pred_Ens_now!D10-pred_Ens_now!$B10) -> 0.41661 | E10: =abs(pred_Ens_now!E10-pred_Ens_now!$B10) -> 0.35132677 | F10: =abs(pred_Ens_now!F10-pred_Ens_now!$B10) -> 0.4274195 | H10: =abs(pred_Ens_now!H10-pred_Ens_now!$B10) -> 0.49558966 | J10: =abs(pred_Ens_now!J10-pred_Ens_now!$B10) -> 0.546515 | K10: =abs(pred_Ens_now!K10-pred_Ens_now!$B10) -> 0.38958195 | L10: =abs(pred_Ens_now!L10-pred_Ens_now!$B10) -> 0.36588991
A11: 201806 | B11: 0.7 | C11: =abs(pred_Ens_now!C11-pred_Ens_now!$B11) -> 0.38374 | D11: =abs(pred_Ens_now!D11-pred_Ens_now!$B11) -> 0.61321681 | E11: =abs(pred_Ens_now!E11-pred_Ens_now!$B11) -> 0.021270724 | F11: =abs(pred_Ens_now!F11-pred_Ens_now!$B11) -> 0.08493605 | H11: =abs(pred_Ens_now!H11-pred_Ens_now!$B11) -> 0.38374 | J11: =abs(pred_Ens_now!J11-pred_Ens_now!$B11) -> 0.137201 | K11: =abs(pred_Ens_now!K11-pred_Ens_now!$B11) -> 0.069749832 | L11: =abs(pred_Ens_now!L11-pred_Ens_now!$B11) -> 0.00078742241
A12: 201809 | B12: 0.6 | C12: =abs(pred_Ens_now!C12-pred_Ens_now!$B12) -> 0.279481 | D12: =abs(pred_Ens_now!D12-pred_Ens_now!$B12) -> 0.4800163 | E12: =abs(pred_Ens_now!E12-pred_Ens_now!$B12) -> 0.039210672 | F12: =abs(pred_Ens_now!F12-pred_Ens_now!$B12) -> 0.00749367 | H12: =abs(pred_Ens_now!H12-pred_Ens_now!$B12) -> 0.44576878 | J12: =abs(pred_Ens_now!J12-pred_Ens_now!$B12) -> 0.004256361 | K12: =abs(pred_Ens_now!K12-pred_Ens_now!$B12) -> 0.10742781 | L12: =abs(pred_Ens_now!L12-pred_Ens_now!$B12) -> 0.028942887
A13: 201812 | B13: 0.6 | C13: =abs(pred_Ens_now!C13-pred_Ens_now!$B13) -> 0.62169 | D13: =abs(pred_Ens_now!D13-pred_Ens_now!$B13) -> 0.53997129 | E13: =abs(pred_Ens_now!E13-pred_Ens_now!$B13) -> 0.17463931 | F13: =abs(pred_Ens_now!F13-pred_Ens_now!$B13) -> 0.21911013 | H13: =abs(pred_Ens_now!H13-pred_Ens_now!$B13) -> 0.149574 | J13: =abs(pred_Ens_now!J13-pred_Ens_now!$B13) -> 0.14688172 | K13: =abs(pred_Ens_now!K13-pred_Ens_now!$B13) -> 0.064051382 | L13: =abs(pred_Ens_now!L13-pred_Ens_now!$B13) -> 0.17537324
A14: 201903 | B14: -0.1 | C14: =abs(pred_Ens_now!C14-pred_Ens_now!$B14) -> 0.467977 | D14: =abs(pred_Ens_now!D14-pred_Ens_now!$B14) -> 0.85638 | E14: =abs(pred_Ens_now!E14-pred_Ens_now!$B14) -> 0.33252975 | F14: =abs(pred_Ens_now!F14-pred_Ens_now!$B14) -> 0.359024 | H14: =abs(pred_Ens_now!H14-pred_Ens_now!$B14) -> 0.256505 | J14: =abs(pred_Ens_now!J14-pred_Ens_now!$B14) -> 0.013809949 | K14: =abs(pred_Ens_now!K14-pred_Ens_now!$B14) -> 0.10005237 | L14: =abs(pred_Ens_now!L14-pred_Ens_now!$B14) -> 0.086389623
A15: 201906 | B15: 1.1 | C15: =abs(pred_Ens_now!C15-pred_Ens_now!$B15) -> 0.5871112 | D15: =abs(pred_Ens_now!D15-pred_Ens_now!$B15) -> 0.20905509 | E15: =abs(pred_Ens_now!E15-pred_Ens_now!$B15) -> 0.14443574 | F15: =abs(pred_Ens_now!F15-pred_Ens_now!$B15) -> 0.1730095 | H15: =abs(pred_Ens_now!H15-pred_Ens_now!$B15) -> 0.296762 | J15: =abs(pred_Ens_now!J15-pred_Ens_now!$B15) -> 0.22702054 | K15: =abs(pred_Ens_now!K15-pred_Ens_now!$B15) -> 0.21636504 | L15: =abs(pred_Ens_now!L15-pred_Ens_now!$B15) -> 0.22708188
A16: 201909 | B16: 0.4 | C16: =abs(pred_Ens_now!C16-pred_Ens_now!$B16) -> 0.048457 | D16: =abs(pred_Ens_now!D16-pred_Ens_now!$B16) -> 0.7893855 | E16: =abs(pred_Ens_now!E16-pred_Ens_now!$B16) -> 0.3006273 | F16: =abs(pred_Ens_now!F16-pred_Ens_now!$B16) -> 0.29009547 | H16: =abs(pred_Ens_now!H16-pred_Ens_now!$B16) -> 0.30446534 | J16: =abs(pred_Ens_now!J16-pred_Ens_now!$B16) -> 0.070158258 | K16: =abs(pred_Ens_now!K16-pred_Ens_now!$B16) -> 0.18390685 | L16: =abs(pred_Ens_now!L16-pred_Ens_now!$B16) -> 0.077143753
A17: 201912 | B17: 1.2 | C17: =abs(pred_Ens_now!C17-pred_Ens_now!$B17) -> 1.1229792 | D17: =abs(pred_Ens_now!D17-pred_Ens_now!$B17) -> 0.075382592 | E17: =abs(pred_Ens_now!E17-pred_Ens_now!$B17) -> 0.52855054 | F17: =abs(pred_Ens_now!F17-pred_Ens_now!$B17) -> 0.53713075 | H17: =abs(pred_Ens_now!H17-pred_Ens_now!$B17) -> 0.3021984 | J17: =abs(pred_Ens_now!J17-pred_Ens_now!$B17) -> 0.3021984 | K17: =abs(pred_Ens_now!K17-pred_Ens_now!$B17) -> 0.48594218 | L17: =abs(pred_Ens_now!L17-pred_Ens_now!$B17) -> 0.40970713
A18: 202003 | B18: -1.3 | C18: =abs(pred_Ens_now!C18-pred_Ens_now!$B18) -> 0.57868134 | D18: =abs(pred_Ens_now!D18-pred_Ens_now!$B18) -> 2.139619 | E18: =abs(pred_Ens_now!E18-pred_Ens_now!$B18) -> 1.4121053 | F18: =abs(pred_Ens_now!F18-pred_Ens_now!$B18) -> 1.3450044 | H18: =abs(pred_Ens_now!H18-pred_Ens_now!$B18) -> 1.579367 | J18: =abs(pred_Ens_now!J18-pred_Ens_now!$B18) -> 1.5318738 | K18: =abs(pred_Ens_now!K18-pred_Ens_now!$B18) -> 1.3663776 | L18: =abs(pred_Ens_now!L18-pred_Ens_now!$B18) -> 1.3625784
... A29: 202212 | B29: -0.3 | C29: =abs(pred_Ens_now!C29-pred_Ens_now!$B29) -> 0.63253 | D29: =abs(pred_Ens_now!D29-pred_Ens_now!$B29) -> 0.75885565 | E29: =abs(pred_Ens_now!E29-pred_Ens_now!$B29) -> 0.0099344122 | F29: =abs(pred_Ens_now!F29-pred_Ens_now!$B29) -> 0.1367855 | H29: =abs(pred_Ens_now!H29-pred_Ens_now!$B29) -> 0.25036 | J29: =abs(pred_Ens_now!J29-pred_Ens_now!$B29) -> 0.26236 | K29: =abs(pred_Ens_now!K29-pred_Ens_now!$B29) -> 0.15194811 | L29: =abs(pred_Ens_now!L29-pred_Ens_now!$B29) -> 0.28501
A30: 202303 | B30: 0.3
B32: MAE | C32: =AVERAGE(C2:C30) -> 0.71676789 | D32: =AVERAGE(D2:D30) -> 0.94312144 | E32: =AVERAGE(E2:E30) -> 0.37216383 | F32: =AVERAGE(F2:F30) -> 0.41241194 | H32: =AVERAGE(H2:H30) -> 0.52869105 | J32: =AVERAGE(J2:J30) -> 0.48626782 | K32: =AVERAGE(K2:K30) -> 0.45084369 | L32: =AVERAGE(L2:L30) -> 0.41829562
B33: RMSE | C33: =(sumsq(C2:C30)/count(C2:C30))^(0.5) -> 1.1269117 | D33: =(sumsq(D2:D30)/count(D2:D30))^(0.5) -> 1.196575 | E33: =(sumsq(E2:E30)/count(E2:E30))^(0.5) -> 0.52398759 | F33: =(sumsq(F2:F30)/count(F2:F30))^(0.5) -> 0.58635257 | H33: =(sumsq(H2:H30)/count(H2:H30))^(0.5) -> 0.69749144 | J33: =(sumsq(J2:J30)/count(J2:J30))^(0.5) -> 0.72068921 | K33: =(sumsq(K2:K30)/count(K2:K30))^(0.5) -> 0.69085093 | L33: =(sumsq(L2:L30)/count(L2:L30))^(0.5) -> 0.64865872
B34: MAX | C34: =MAX(C2:C30) -> 4.82413 | D34: =MAX(D2:D30) -> 3.3922768 | E34: =MAX(E2:E30) -> 1.4375885 | F34: =MAX(F2:F30) -> 1.9269455 | H34: =MAX(H2:H30) -> 1.83879 | J34: =MAX(J2:J30) -> 2.2830904 | K34: =MAX(K2:K30) -> 2.3713174 | L34: =MAX(L2:L30) -> 2.049404
B36: MAE | C36: =AVERAGE(C7:C30) -> 0.79211402 | D36: =AVERAGE(D7:D30) -> 1.0259066 | E36: =AVERAGE(E7:E30) -> 0.40922773 | F36: =AVERAGE(F7:F30) -> 0.45818633 | H36: =AVERAGE(H7:H30) -> 0.52869105 | J36: =AVERAGE(J7:J30) -> 0.48626782 | K36: =AVERAGE(K7:K30) -> 0.45084369 | L36: =AVERAGE(L7:L30) -> 0.41829562
B37: RMSE | C37: =(sumsq(C7:C30)/count(C7:C30))^(0.5) -> 1.2224658 | D37: =(sumsq(D7:D30)/count(D7:D30))^(0.5) -> 1.2931854 | E37: =(sumsq(E7:E30)/count(E7:E30))^(0.5) -> 0.5676368 | F37: =(sumsq(F7:F30)/count(F7:F30))^(0.5) -> 0.63744871 | H37: =(sumsq(H7:H30)/count(H7:H30))^(0.5) -> 0.69749144 | J37: =(sumsq(J7:J30)/count(J7:J30))^(0.5) -> 0.72068921 | K37: =(sumsq(K7:K30)/count(K7:K30))^(0.5) -> 0.69085093 | L37: =(sumsq(L7:L30)/count(L7:L30))^(0.5) -> 0.64865872
B38: MAX | C38: =MAX(C7:C30) -> 4.82413 | D38: =MAX(D7:D30) -> 3.3922768 | E38: =MAX(E7:E30) -> 1.4375885 | F38: =MAX(F7:F30) -> 1.9269455 | H38: =MAX(H7:H30) -> 1.83879 | J38: =MAX(J7:J30) -> 2.2830904 | K38: =MAX(K7:K30) -> 2.3713174 | L38: =MAX(L7:L30) -> 2.049404
B40: MAE | C40: =AVERAGE(C7:C17) -> 0.56395705 | D40: =AVERAGE(D7:D17) -> 0.59803096 | E40: =AVERAGE(E7:E17) -> 0.34260533 | F40: =AVERAGE(F7:F17) -> 0.35479196 | H40: =AVERAGE(H7:H17) -> 0.41589216 | J40: =AVERAGE(J7:J17) -> 0.32143102 | K40: =AVERAGE(K7:K17) -> 0.34021216 | L40: =AVERAGE(L7:L17) -> 0.33410971
B41: RMSE | C41: =(sumsq(C7:C17)/count(C7:C17))^(0.5) -> 0.6468735 | D41: =(sumsq(D7:D17)/count(D7:D17))^(0.5) -> 0.72248158 | E41: =(sumsq(E7:E17)/count(E7:E17))^(0.5) -> 0.45333999 | F41: =(sumsq(F7:F17)/count(F7:F17))^(0.5) -> 0.45212167 | H41: =(sumsq(H7:H17)/count(H7:H17))^(0.5) -> 0.50110498 | J41: =(sumsq(J7:J17)/count(J7:J17))^(0.5) -> 0.45478465 | K41: =(sumsq(K7:K17)/count(K7:K17))^(0.5) -> 0.46130924 | L41: =(sumsq(L7:L17)/count(L7:L17))^(0.5) -> 0.47952963
B42: MAX | C42: =MAX(C7:C17) -> 1.124247 | D42: =MAX(D7:D17) -> 1.687553 | E42: =MAX(E7:E17) -> 1.0633448 | F42: =MAX(F7:F17) -> 1.0313022 | H42: =MAX(H7:H17) -> 1.195778 | J42: =MAX(J7:J17) -> 1.124247 | K42: =MAX(K7:K17) -> 1.0240216 | L42: =MAX(L7:L17) -> 1.0791017
B44: MAE | C44: =AVERAGE(C18:C25) -> 1.2683436 | D44: =AVERAGE(D18:D25) -> 1.7659681 | E44: =AVERAGE(E18:E25) -> 0.62291025 | F44: =AVERAGE(F18:F25) -> 0.71827303 | H44: =AVERAGE(H18:H25) -> 0.78140035 | J44: =AVERAGE(J18:J25) -> 0.81961283 | K44: =AVERAGE(K18:K25) -> 0.72100557 | L44: =AVERAGE(L18:L25) -> 0.63969498
B45: RMSE | C45: =(sumsq(C18:C25)/count(C18:C25))^(0.5) -> 1.8969313 | D45: =(sumsq(D18:D25)/count(D18:D25))^(0.5) -> 1.9540702 | E45: =(sumsq(E18:E25)/count(E18:E25))^(0.5) -> 0.79105071 | F45: =(sumsq(F18:F25)/count(F18:F25))^(0.5) -> 0.92737711 | H45: =(sumsq(H18:H25)/count(H18:H25))^(0.5) -> 0.99323834 | J45: =(sumsq(J18:J25)/count(J18:J25))^(0.5) -> 1.0765385 | K45: =(sumsq(K18:K25)/count(K18:K25))^(0.5) -> 1.024833 | L45: =(sumsq(L18:L25)/count(L18:L25))^(0.5) -> 0.92727536
B46: MAX | C46: =MAX(C18:C25) -> 4.82413 | D46: =MAX(D18:D25) -> 3.3922768 | E46: =MAX(E18:E25) -> 1.4375885 | F46: =MAX(F18:F25) -> 1.9269455 | H46: =MAX(H18:H25) -> 1.83879 | J46: =MAX(J18:J25) -> 2.2830904 | K46: =MAX(K18:K25) -> 2.3713174 | L46: =MAX(L18:L25) -> 2.049404
B48: MAE | C48: =AVERAGE(C20:C30) -> 0.66122835 | D48: =AVERAGE(D20:D30) -> 1.1485615 | E48: =AVERAGE(E20:E30) -> 0.27938853 | F48: =AVERAGE(F20:F30) -> 0.3363624 | H48: =AVERAGE(H20:H30) -> 0.41669234 | J48: =AVERAGE(J20:J30) -> 0.38334544 | K48: =AVERAGE(K20:K30) -> 0.28893762 | L48: =AVERAGE(L20:L30) -> 0.253361
B49: RMSE | C49: =(sumsq(C20:C30)/count(C20:C30))^(0.5) -> 0.78496614 | D49: =(sumsq(D20:D30)/count(D20:D30))^(0.5) -> 1.2898165 | E49: =(sumsq(E20:E30)/count(E20:E30))^(0.5) -> 0.33007191 | F49: =(sumsq(F20:F30)/count(F20:F30))^(0.5) -> 0.39687906 | H49: =(sumsq(H20:H30)/count(H20:H30))^(0.5) -> 0.50513881 | J49: =(sumsq(J20:J30)/count(J20:J30))^(0.5) -> 0.4595409 | K49: =(sumsq(K20:K30)/count(K20:K30))^(0.5) -> 0.33857388 | L49: =(sumsq(L20:L30)/count(L20:L30))^(0.5) -> 0.33035213
B50: MAX | C50: =MAX(C20:C30) -> 1.477096 | D50: =MAX(D20:D30) -> 2.095491 | E50: =MAX(E20:E30) -> 0.69514975 | F50: =MAX(F20:F30) -> 0.74611828 | H50: =MAX(H20:H30) -> 1.085918 | J50: =MAX(J20:J30) -> 0.80601951 | K50: =MAX(K20:K30) -> 0.73551896 | L50: =MAX(L20:L30) -> 0.74413675

Sheet Ens_now작업
B1: GDP(SA) True | C1: DFM | D1: BEM1 | E1: BEM2 | F1: BEM3 | H1: LBVAR | I1: TFM | J1: T-M | K1: VAR | L1: SVR-KNN | M1: CRNN | O1: RF-DVS | P1: S-XGB | Q1: LQR | R1: OptimARIMA | AA1: TEXT | AB1: MIN_item | AC1: MIN
A2: 201603 | B2: 0.3
A3: 201606 | B3: 1.2
A4: 201609 | B4: 0.4
A5: 201612 | B5: 0.6
A6: 201703 | B6: 1 | C6: =average(err_GDP_now!C2:C5) -> 0.29367304 | D6: =average(err_GDP_now!D2:D5) -> 0.1864365 | E6: =average(err_GDP_now!E2:E5) -> 0.1911775 | F6: =average(err_GDP_now!F2:F5) -> 0.19473525 | H6: =average(err_GDP_now!H2:H5) -> 0.464135 | I6: =average(err_GDP_now!I2:I5) -> 0.3335034 | J6: =average(err_GDP_now!J2:J5) -> 0.31262993 | K6: =average(err_GDP_now!K2:K5) -> 0.390236 | L6: =average(err_GDP_now!L2:L5) -> 0.23435091 | M6: =average(err_GDP_now!M2:M5) -> 0.46458401 | O6: =average(err_GDP_now!O2:O5) -> 0.31551155 | P6: =average(err_GDP_now!P2:P5) -> 0.46337588 | Q6: =average(err_GDP_now!Q2:Q5) -> 0.25054075 | AA6: =average(err_GDP_now!AA2:AA5) -> 0.464135 | AB6: =index($C$1:$AA$1, match(min(C6:AA6),C6:AA6,0)) -> BEM1 | AC6: =min(C6:AA6) -> 0.1864365
A7: 201706 | B7: 0.8 | C7: =average(err_GDP_now!C3:C6) -> 0.26214348 | D7: =average(err_GDP_now!D3:D6) -> 0.19119975 | E7: =average(err_GDP_now!E3:E6) -> 0.16392425 | F7: =average(err_GDP_now!F3:F6) -> 0.1898295 | H7: =average(err_GDP_now!H3:H6) -> 0.440463 | I7: =average(err_GDP_now!I3:I6) -> 0.30614807 | J7: =average(err_GDP_now!J3:J6) -> 0.19465858 | K7: =average(err_GDP_now!K3:K6) -> 0.29403425 | L7: =average(err_GDP_now!L3:L6) -> 0.24802003 | M7: =average(err_GDP_now!M3:M6) -> 0.37226284 | O7: =average(err_GDP_now!O3:O6) -> 0.30185809 | P7: =average(err_GDP_now!P3:P6) -> 0.42223538 | Q7: =average(err_GDP_now!Q3:Q6) -> 0.2681715 | AA7: =average(err_GDP_now!AA3:AA6) -> 0.440463 | AB7: =index($C$1:$AA$1, match(min(C7:AA7),C7:AA7,0)) -> BEM2 | AC7: =min(C7:AA7) -> 0.16392425
A8: 201709 | B8: 1.4 | C8: =average(err_GDP_now!C4:C7) -> 0.26247344 | D8: =average(err_GDP_now!D4:D7) -> 0.19135075 | E8: =average(err_GDP_now!E4:E7) -> 0.15746475 | F8: =average(err_GDP_now!F4:F7) -> 0.16664875 | H8: =average(err_GDP_now!H4:H7) -> 0.2560005 | I8: =average(err_GDP_now!I4:I7) -> 0.30510694 | J8: =average(err_GDP_now!J4:J7) -> 0.19804005 | K8: =average(err_GDP_now!K4:K7) -> 0.28052375 | L8: =average(err_GDP_now!L4:L7) -> 0.26822937 | M8: =average(err_GDP_now!M4:M7) -> 0.21964673 | O8: =average(err_GDP_now!O4:O7) -> 0.19628718 | P8: =average(err_GDP_now!P4:P7) -> 0.3815835 | Q8: =average(err_GDP_now!Q4:Q7) -> 0.14552275 | AA8: =average(err_GDP_now!AA4:AA7) -> 0.2560005 | AB8: =index($C$1:$AA$1, match(min(C8:AA8),C8:AA8,0)) -> LQR | AC8: =min(C8:AA8) -> 0.14552275
A9: 201712 | B9: -0.3 | C9: =average(err_GDP_now!C5:C8) -> 0.39049568 | D9: =average(err_GDP_now!D5:D8) -> 0.408937 | E9: =average(err_GDP_now!E5:E8) -> 0.39755275 | F9: =average(err_GDP_now!F5:F8) -> 0.345645 | H9: =average(err_GDP_now!H5:H8) -> 0.22943375 | I9: =average(err_GDP_now!I5:I8) -> 0.33086442 | J9: =average(err_GDP_now!J5:J8) -> 0.25774396 | K9: =average(err_GDP_now!K5:K8) -> 0.252965 | L9: =average(err_GDP_now!L5:L8) -> 0.37439228 | M9: =average(err_GDP_now!M5:M8) -> 0.32645173 | O9: =average(err_GDP_now!O5:O8) -> 0.23019476 | P9: =average(err_GDP_now!P5:P8) -> 0.37954265 | Q9: =average(err_GDP_now!Q5:Q8) -> 0.26926575 | AA9: =average(err_GDP_now!AA5:AA8) -> 0.22943375 | AB9: =index($C$1:$AA$1, match(min(C9:AA9),C9:AA9,0)) -> LBVAR | AC9: =min(C9:AA9) -> 0.22943375
A10: 201803 | B10: 1.3 | C10: =average(err_GDP_now!C6:C9) -> 0.51026176 | D10: =average(err_GDP_now!D6:D9) -> 0.69827975 | E10: =average(err_GDP_now!E6:E9) -> 0.63048425 | F10: =average(err_GDP_now!F6:F9) -> 0.61657375 | H10: =average(err_GDP_now!H6:H9) -> 0.6452605 | I10: =average(err_GDP_now!I6:I9) -> 0.50703741 | J10: =average(err_GDP_now!J6:J9) -> 0.48805535 | K10: =average(err_GDP_now!K6:K9) -> 0.3900835 | L10: =average(err_GDP_now!L6:L9) -> 0.40630468 | M10: =average(err_GDP_now!M6:M9) -> 0.49115198 | O10: =average(err_GDP_now!O6:O9) -> 0.45734614 | P10: =average(err_GDP_now!P6:P9) -> 0.52937145 | Q10: =average(err_GDP_now!Q6:Q9) -> 0.39054375 | AA10: =average(err_GDP_now!AA6:AA9) -> 0.6452605 | AB10: =index($C$1:$AA$1, match(min(C10:AA10),C10:AA10,0)) -> VAR | AC10: =min(C10:AA10) -> 0.3900835
A11: 201806 | B11: 0.7 | C11: =average(err_GDP_now!C7:C10) -> 0.53898324 | D11: =average(err_GDP_now!D7:D10) -> 0.82362025 | E11: =average(err_GDP_now!E7:E10) -> 0.72899425 | F11: =average(err_GDP_now!F7:F10) -> 0.750541 | H11: =average(err_GDP_now!H7:H10) -> 0.693787 | I11: =average(err_GDP_now!I7:I10) -> 0.57089999 | J11: =average(err_GDP_now!J7:J10) -> 0.54971852 | K11: =average(err_GDP_now!K7:K10) -> 0.45247725 | L11: =average(err_GDP_now!L7:L10) -> 0.40158452 | M11: =average(err_GDP_now!M7:M10) -> 0.56167569 | O11: =average(err_GDP_now!O7:O10) -> 0.4590101 | P11: =average(err_GDP_now!P7:P10) -> 0.6495633 | Q11: =average(err_GDP_now!Q7:Q10) -> 0.51090925 | AA11: =average(err_GDP_now!AA7:AA10) -> 0.693787 | AB11: =index($C$1:$AA$1, match(min(C11:AA11),C11:AA11,0)) -> SVR-KNN | AC11: =min(C11:AA11) -> 0.40158452
A12: 201809 | B12: 0.6 | C12: =average(err_GDP_now!C8:C11) -> 0.53097239 | D12: =average(err_GDP_now!D8:D11) -> 0.74932475 | E12: =average(err_GDP_now!E8:E11) -> 0.68439725 | F12: =average(err_GDP_now!F8:F11) -> 0.6970345 | H12: =average(err_GDP_now!H8:H11) -> 0.76204175 | I12: =average(err_GDP_now!I8:I11) -> 0.5710857 | J12: =average(err_GDP_now!J8:J11) -> 0.551265 | K12: =average(err_GDP_now!K8:K11) -> 0.483524 | L12: =average(err_GDP_now!L8:L11) -> 0.37486074 | M12: =average(err_GDP_now!M8:M11) -> 0.57632478 | O12: =average(err_GDP_now!O8:O11) -> 0.50776629 | P12: =average(err_GDP_now!P8:P11) -> 0.70496462 | Q12: =average(err_GDP_now!Q8:Q11) -> 0.47758275 | AA12: =average(err_GDP_now!AA8:AA11) -> 0.76204175 | AB12: =index($C$1:$AA$1, match(min(C12:AA12),C12:AA12,0)) -> SVR-KNN | AC12: =min(C12:AA12) -> 0.37486074
A13: 201812 | B13: 0.6 | C13: =average(err_GDP_now!C9:C12) -> 0.45819807 | D13: =average(err_GDP_now!D9:D12) -> 0.490328 | E13: =average(err_GDP_now!E9:E12) -> 0.434419 | F13: =average(err_GDP_now!F9:F12) -> 0.45398875 | H13: =average(err_GDP_now!H9:H12) -> 0.7140075 | I13: =average(err_GDP_now!I9:I12) -> 0.52695451 | J13: =average(err_GDP_now!J9:J12) -> 0.52139027 | K13: =average(err_GDP_now!K9:K12) -> 0.399011 | L13: =average(err_GDP_now!L9:L12) -> 0.25625731 | M13: =average(err_GDP_now!M9:M12) -> 0.45842702 | O13: =average(err_GDP_now!O9:O12) -> 0.36269004 | P13: =average(err_GDP_now!P9:P12) -> 0.59631948 | Q13: =average(err_GDP_now!Q9:Q12) -> 0.32548 | AA13: =average(err_GDP_now!AA9:AA12) -> 0.7140075 | AB13: =index($C$1:$AA$1, match(min(C13:AA13),C13:AA13,0)) -> SVR-KNN | AC13: =min(C13:AA13) -> 0.25625731
A14: 201903 | B14: -0.1 | C14: =average(err_GDP_now!C10:C13) -> 0.28920097 | D14: =average(err_GDP_now!D10:D13) -> 0.30299825 | E14: =average(err_GDP_now!E10:E13) -> 0.34639875 | F14: =average(err_GDP_now!F10:F13) -> 0.243572 | H14: =average(err_GDP_now!H10:H13) -> 0.32951275 | I14: =average(err_GDP_now!I10:I13) -> 0.29616642 | J14: =average(err_GDP_now!J10:J13) -> 0.23816168 | K14: =average(err_GDP_now!K10:K13) -> 0.176258 | L14: =average(err_GDP_now!L10:L13) -> 0.089946413 | M14: =average(err_GDP_now!M10:M13) -> 0.33956792 | O14: =average(err_GDP_now!O10:O13) -> 0.23686983 | P14: =average(err_GDP_now!P10:P13) -> 0.35298987 | Q14: =average(err_GDP_now!Q10:Q13) -> 0.28232825 | AA14: =average(err_GDP_now!AA10:AA13) -> 0.32951275 | AB14: =index($C$1:$AA$1, match(min(C14:AA14),C14:AA14,0)) -> SVR-KNN | AC14: =min(C14:AA14) -> 0.089946413
A15: 201906 | B15: 1.1 | C15: =average(err_GDP_now!C11:C14) -> 0.29576359 | D15: =average(err_GDP_now!D11:D14) -> 0.15461375 | E15: =average(err_GDP_now!E11:E14) -> 0.2785345 | F15: =average(err_GDP_now!F11:F14) -> 0.16012 | H15: =average(err_GDP_now!H11:H14) -> 0.406979 | I15: =average(err_GDP_now!I11:I14) -> 0.36868686 | J15: =average(err_GDP_now!J11:J14) -> 0.34107172 | K15: =average(err_GDP_now!K11:K14) -> 0.20091075 | L15: =average(err_GDP_now!L11:L14) -> 0.071921441 | M15: =average(err_GDP_now!M11:M14) -> 0.41840125 | O15: =average(err_GDP_now!O11:O14) -> 0.36814813 | P15: =average(err_GDP_now!P11:P14) -> 0.40247354 | Q15: =average(err_GDP_now!Q11:Q14) -> 0.260403 | AA15: =average(err_GDP_now!AA11:AA14) -> 0.406979 | AB15: =index($C$1:$AA$1, match(min(C15:AA15),C15:AA15,0)) -> SVR-KNN | AC15: =min(C15:AA15) -> 0.071921441
A16: 201909 | B16: 0.4 | C16: =average(err_GDP_now!C12:C15) -> 0.23375672 | D16: =average(err_GDP_now!D12:D15) -> 0.21325675 | E16: =average(err_GDP_now!E12:E15) -> 0.307233 | F16: =average(err_GDP_now!F12:F15) -> 0.2339885 | H16: =average(err_GDP_now!H12:H15) -> 0.349763 | I16: =average(err_GDP_now!I12:I15) -> 0.35038058 | J16: =average(err_GDP_now!J12:J15) -> 0.32925865 | K16: =average(err_GDP_now!K12:K15) -> 0.22136275 | L16: =average(err_GDP_now!L12:L15) -> 0.097992144 | M16: =average(err_GDP_now!M12:M15) -> 0.54861428 | O16: =average(err_GDP_now!O12:O15) -> 0.37694175 | P16: =average(err_GDP_now!P12:P15) -> 0.30143311 | Q16: =average(err_GDP_now!Q12:Q15) -> 0.28913025 | AA16: =average(err_GDP_now!AA12:AA15) -> 0.349763 | AB16: =index($C$1:$AA$1, match(min(C16:AA16),C16:AA16,0)) -> SVR-KNN | AC16: =min(C16:AA16) -> 0.097992144
A17: 201912 | B17: 1.2 | C17: =average(err_GDP_now!C13:C16) -> 0.21595211 | D17: =average(err_GDP_now!D13:D16) -> 0.20663125 | E17: =average(err_GDP_now!E13:E16) -> 0.28826375 | F17: =average(err_GDP_now!F13:F16) -> 0.25471025 | H17: =average(err_GDP_now!H13:H16) -> 0.4402365 | I17: =average(err_GDP_now!I13:I16) -> 0.25009511 | J17: =average(err_GDP_now!J13:J16) -> 0.28389045 | K17: =average(err_GDP_now!K13:K16) -> 0.26598675 | L17: =average(err_GDP_now!L13:L16) -> 0.11446762 | M17: =average(err_GDP_now!M13:M16) -> 0.68283389 | O17: =average(err_GDP_now!O13:O16) -> 0.44824716 | P17: =average(err_GDP_now!P13:P16) -> 0.43379246 | Q17: =average(err_GDP_now!Q13:Q16) -> 0.37127475 | AA17: =average(err_GDP_now!AA13:AA16) -> 0.4402365 | AB17: =index($C$1:$AA$1, match(min(C17:AA17),C17:AA17,0)) -> SVR-KNN | AC17: =min(C17:AA17) -> 0.11446762
... A29: 202212 | B29: -0.3 | C29: =average(err_GDP_now!C25:C28) -> 0.47909281 | D29: =average(err_GDP_now!D25:D28) -> 0.16845875 | E29: =average(err_GDP_now!E25:E28) -> 0.17410025 | F29: =average(err_GDP_now!F25:F28) -> 0.21384625 | H29: =average(err_GDP_now!H25:H28) -> 0.39303975 | I29: =average(err_GDP_now!I25:I28) -> 0.2815844 | J29: =average(err_GDP_now!J25:J28) -> 0.28743673 | K29: =average(err_GDP_now!K25:K28) -> 0.56464575 | L29: =average(err_GDP_now!L25:L28) -> 0.20673119 | M29: =average(err_GDP_now!M25:M28) -> 0.41842141 | O29: =average(err_GDP_now!O25:O28) -> 0.3462914 | P29: =average(err_GDP_now!P25:P28) -> 0.31863479 | Q29: =average(err_GDP_now!Q25:Q28) -> 0.3622715 | AA29: =average(err_GDP_now!AA25:AA28) -> 0.39303975 | AB29: =index($C$1:$AA$1, match(min(C29:AA29),C29:AA29,0)) -> BEM1 | AC29: =min(C29:AA29) -> 0.16845875
A30: 202303 | B30: 0.3 | C30: =average(err_GDP_now!C26:C29) -> 0.42405532 | D30: =average(err_GDP_now!D26:D29) -> 0.263844 | E30: =average(err_GDP_now!E26:E29) -> 0.32046375 | F30: =average(err_GDP_now!F26:F29) -> 0.2294765 | H30: =average(err_GDP_now!H26:H29) -> 0.4237145 | I30: =average(err_GDP_now!I26:I29) -> 0.15103969 | J30: =average(err_GDP_now!J26:J29) -> 0.30736764 | K30: =average(err_GDP_now!K26:K29) -> 0.5253255 | L30: =average(err_GDP_now!L26:L29) -> 0.27249345 | M30: =average(err_GDP_now!M26:M29) -> 0.30817398 | O30: =average(err_GDP_now!O26:O29) -> 0.29656344 | P30: =average(err_GDP_now!P26:P29) -> 0.35264828 | Q30: =average(err_GDP_now!Q26:Q29) -> 0.38207275 | AA30: =average(err_GDP_now!AA26:AA29) -> 0.4237145
B32: MAE | C32: =AVERAGE(C2:C30) -> 0.58265505 | D32: =AVERAGE(D2:D30) -> 0.4418673 | E32: =AVERAGE(E2:E30) -> 0.42298773 | F32: =AVERAGE(F2:F30) -> 0.50476696 | H32: =AVERAGE(H2:H30) -> 0.86258969 | I32: =AVERAGE(I2:I30) -> 0.50405398 | J32: =AVERAGE(J2:J30) -> 0.5463631 | K32: =AVERAGE(K2:K30) -> 0.54702894 | L32: =AVERAGE(L2:L30) -> 0.36997989 | M32: =AVERAGE(M2:M30) -> 0.62372844 | O32: =AVERAGE(O2:O30) -> 0.5423839 | P32: =AVERAGE(P2:P30) -> 0.51518434 | Q32: =AVERAGE(Q2:Q30) -> 0.43255776 | AA32: =AVERAGE(AA2:AA30) -> 0.86258969 | AC32: =AVERAGE(AC2:AC30) -> 0.29000852
B33: RMSE | C33: =(sumsq(C2:C30)/count(C2:C30))^(0.5) -> 0.66659309 | D33: =(sumsq(D2:D30)/count(D2:D30))^(0.5) -> 0.51939698 | E33: =(sumsq(E2:E30)/count(E2:E30))^(0.5) -> 0.48681546 | F33: =(sumsq(F2:F30)/count(F2:F30))^(0.5) -> 0.63237823 | H33: =(sumsq(H2:H30)/count(H2:H30))^(0.5) -> 1.1362936 | I33: =(sumsq(I2:I30)/count(I2:I30))^(0.5) -> 0.55657597 | J33: =(sumsq(J2:J30)/count(J2:J30))^(0.5) -> 0.66785466 | K33: =(sumsq(K2:K30)/count(K2:K30))^(0.5) -> 0.63210214 | L33: =(sumsq(L2:L30)/count(L2:L30))^(0.5) -> 0.46396861 | M33: =(sumsq(M2:M30)/count(M2:M30))^(0.5) -> 0.71431885 | O33: =(sumsq(O2:O30)/count(O2:O30))^(0.5) -> 0.62850033 | P33: =(sumsq(P2:P30)/count(P2:P30))^(0.5) -> 0.54562515 | Q33: =(sumsq(Q2:Q30)/count(Q2:Q30))^(0.5) -> 0.48210442 | AA33: =(sumsq(AA2:AA30)/count(AA2:AA30))^(0.5) -> 1.1362936 | AC33: =(sumsq(AC2:AC30)/count(AC2:AC30))^(0.5) -> 0.35859703
B34: MAX | C34: =MAX(C2:C30) -> 1.2593144 | D34: =MAX(D2:D30) -> 1.0166243 | E34: =MAX(E2:E30) -> 0.92149 | F34: =MAX(F2:F30) -> 1.4480315 | H34: =MAX(H2:H30) -> 2.6363747 | I34: =MAX(I2:I30) -> 1.0167373 | J34: =MAX(J2:J30) -> 1.4754709 | K34: =MAX(K2:K30) -> 1.3534922 | L34: =MAX(L2:L30) -> 1.0484591 | M34: =MAX(M2:M30) -> 1.4743734 | O34: =MAX(O2:O30) -> 1.3076957 | P34: =MAX(P2:P30) -> 0.9225919 | Q34: =MAX(Q2:Q30) -> 0.996187 | AA34: =MAX(AA2:AA30) -> 2.6363747 | AC34: =MAX(AC2:AC30) -> 0.921199

Sheet Ens_now작업2
B1: GDP(SA) True | C1: DFM | D1: BEM1 | E1: BEM2 | F1: BEM3 | H1: LBVAR | I1: TFM | J1: T-M | K1: VAR | L1: SVR-KNN | M1: CRNN | O1: RF-DVS | P1: S-XGB | Q1: LQR | R1: OptimARIMA | AA1: TEXT | AB1: MIN_item | AC1: MIN
A2: 201603 | B2: 0.3
A3: 201606 | B3: 1.2
A4: 201609 | B4: 0.4
A5: 201612 | B5: 0.6
A6: 201703 | B6: 1 | AA6: =average(err_GDP_now!AA2:AA5) -> 0.464135 | AB6: =index($C$1:$AA$1, match(min(C6:AA6),C6:AA6,0)) -> TEXT | AC6: =min(C6:AA6) -> 0.464135
A7: 201706 | B7: 0.8 | C7: =if(rank('Ens_now작업'!C6,'Ens_now작업'!$C6:$Z6,1)<=5,pred_GDP_now!C7,"") | D7: =if(rank('Ens_now작업'!D6,'Ens_now작업'!$C6:$Z6,1)<=5,pred_GDP_now!D7,"") -> 1.108525 | E7: =if(rank('Ens_now작업'!E6,'Ens_now작업'!$C6:$Z6,1)<=5,pred_GDP_now!E7,"") -> 1.126052 | F7: =if(rank('Ens_now작업'!F6,'Ens_now작업'!$C6:$Z6,1)<=5,pred_GDP_now!F7,"") -> 1.015314 | H7: =if(rank('Ens_now작업'!H6,'Ens_now작업'!$C6:$Z6,1)<=5,pred_GDP_now!H7,"") | I7: =if(rank('Ens_now작업'!I6,'Ens_now작업'!$C6:$Z6,1)<=5,pred_GDP_now!I7,"") | J7: =if(rank('Ens_now작업'!J6,'Ens_now작업'!$C6:$Z6,1)<=5,pred_GDP_now!J7,"") | K7: =if(rank('Ens_now작업'!K6,'Ens_now작업'!$C6:$Z6,1)<=5,pred_GDP_now!K7,"") | L7: =if(rank('Ens_now작업'!L6,'Ens_now작업'!$C6:$Z6,1)<=5,pred_GDP_now!L7,"") -> 1.0296328 | M7: =if(rank('Ens_now작업'!M6,'Ens_now작업'!$C6:$Z6,1)<=5,pred_GDP_now!M7,"") | O7: =if(rank('Ens_now작업'!O6,'Ens_now작업'!$C6:$Z6,1)<=5,pred_GDP_now!O7,"") | P7: =if(rank('Ens_now작업'!P6,'Ens_now작업'!$C6:$Z6,1)<=5,pred_GDP_now!P7,"") | Q7: =if(rank('Ens_now작업'!Q6,'Ens_now작업'!$C6:$Z6,1)<=5,pred_GDP_now!Q7,"") -> 0.945407 | AA7: =average(err_GDP_now!AA3:AA6) -> 0.440463 | AB7: =index($C$1:$AA$1, match(min(C7:AA7),C7:AA7,0)) -> TEXT | AC7: =min(C7:AA7) -> 0.440463
A8: 201709 | B8: 1.4 | C8: =if(rank('Ens_now작업'!C7,'Ens_now작업'!$C7:$Z7,1)<=5,pred_GDP_now!C8,"") | D8: =if(rank('Ens_now작업'!D7,'Ens_now작업'!$C7:$Z7,1)<=5,pred_GDP_now!D8,"") -> 0.287701 | E8: =if(rank('Ens_now작업'!E7,'Ens_now작업'!$C7:$Z7,1)<=5,pred_GDP_now!E8,"") -> 0.275753 | F8: =if(rank('Ens_now작업'!F7,'Ens_now작업'!$C7:$Z7,1)<=5,pred_GDP_now!F8,"") -> 0.399241 | H8: =if(rank('Ens_now작업'!H7,'Ens_now작업'!$C7:$Z7,1)<=5,pred_GDP_now!H8,"") | I8: =if(rank('Ens_now작업'!I7,'Ens_now작업'!$C7:$Z7,1)<=5,pred_GDP_now!I8,"") | J8: =if(rank('Ens_now작업'!J7,'Ens_now작업'!$C7:$Z7,1)<=5,pred_GDP_now!J8,"") -> 0.8347323 | K8: =if(rank('Ens_now작업'!K7,'Ens_now작업'!$C7:$Z7,1)<=5,pred_GDP_now!K8,"") | L8: =if(rank('Ens_now작업'!L7,'Ens_now작업'!$C7:$Z7,1)<=5,pred_GDP_now!L8,"") -> 0.92132989 | M8: =if(rank('Ens_now작업'!M7,'Ens_now작업'!$C7:$Z7,1)<=5,pred_GDP_now!M8,"") | O8: =if(rank('Ens_now작업'!O7,'Ens_now작업'!$C7:$Z7,1)<=5,pred_GDP_now!O8,"") | P8: =if(rank('Ens_now작업'!P7,'Ens_now작업'!$C7:$Z7,1)<=5,pred_GDP_now!P8,"") | Q8: =if(rank('Ens_now작업'!Q7,'Ens_now작업'!$C7:$Z7,1)<=5,pred_GDP_now!Q8,"") | AA8: =average(err_GDP_now!AA4:AA7) -> 0.2560005 | AB8: =index($C$1:$AA$1, match(min(C8:AA8),C8:AA8,0)) -> TEXT | AC8: =min(C8:AA8) -> 0.2560005
A9: 201712 | B9: -0.3 | C9: =if(rank('Ens_now작업'!C8,'Ens_now작업'!$C8:$Z8,1)<=5,pred_GDP_now!C9,"") | D9: =if(rank('Ens_now작업'!D8,'Ens_now작업'!$C8:$Z8,1)<=5,pred_GDP_now!D9,"") -> 0.952379 | E9: =if(rank('Ens_now작업'!E8,'Ens_now작업'!$C8:$Z8,1)<=5,pred_GDP_now!E9,"") -> 0.673771 | F9: =if(rank('Ens_now작업'!F8,'Ens_now작업'!$C8:$Z8,1)<=5,pred_GDP_now!F9,"") -> 0.895778 | H9: =if(rank('Ens_now작업'!H8,'Ens_now작업'!$C8:$Z8,1)<=5,pred_GDP_now!H9,"") | I9: =if(rank('Ens_now작업'!I8,'Ens_now작업'!$C8:$Z8,1)<=5,pred_GDP_now!I9,"") | J9: =if(rank('Ens_now작업'!J8,'Ens_now작업'!$C8:$Z8,1)<=5,pred_GDP_now!J9,"") | K9: =if(rank('Ens_now작업'!K8,'Ens_now작업'!$C8:$Z8,1)<=5,pred_GDP_now!K9,"") | L9: =if(rank('Ens_now작업'!L8,'Ens_now작업'!$C8:$Z8,1)<=5,pred_GDP_now!L9,"") | M9: =if(rank('Ens_now작업'!M8,'Ens_now작업'!$C8:$Z8,1)<=5,pred_GDP_now!M9,"") | O9: =if(rank('Ens_now작업'!O8,'Ens_now작업'!$C8:$Z8,1)<=5,pred_GDP_now!O9,"") -> 0.74325214 | P9: =if(rank('Ens_now작업'!P8,'Ens_now작업'!$C8:$Z8,1)<=5,pred_GDP_now!P9,"") | Q9: =if(rank('Ens_now작업'!Q8,'Ens_now작업'!$C8:$Z8,1)<=5,pred_GDP_now!Q9,"") -> 0.354928 | AA9: =average(err_GDP_now!AA5:AA8) -> 0.22943375 | AB9: =index($C$1:$AA$1, match(min(C9:AA9),C9:AA9,0)) -> TEXT | AC9: =min(C9:AA9) -> 0.22943375
A10: 201803 | B10: 1.3 | C10: =if(rank('Ens_now작업'!C9,'Ens_now작업'!$C9:$Z9,1)<=5,pred_GDP_now!C10,"") | D10: =if(rank('Ens_now작업'!D9,'Ens_now작업'!$C9:$Z9,1)<=5,pred_GDP_now!D10,"") | E10: =if(rank('Ens_now작업'!E9,'Ens_now작업'!$C9:$Z9,1)<=5,pred_GDP_now!E10,"") | F10: =if(rank('Ens_now작업'!F9,'Ens_now작업'!$C9:$Z9,1)<=5,pred_GDP_now!F10,"") | H10: =if(rank('Ens_now작업'!H9,'Ens_now작업'!$C9:$Z9,1)<=5,pred_GDP_now!H10,"") -> 0.753485 | I10: =if(rank('Ens_now작업'!I9,'Ens_now작업'!$C9:$Z9,1)<=5,pred_GDP_now!I10,"") | J10: =if(rank('Ens_now작업'!J9,'Ens_now작업'!$C9:$Z9,1)<=5,pred_GDP_now!J10,"") -> 1.005438 | K10: =if(rank('Ens_now작업'!K9,'Ens_now작업'!$C9:$Z9,1)<=5,pred_GDP_now!K10,"") -> 0.937068 | L10: =if(rank('Ens_now작업'!L9,'Ens_now작업'!$C9:$Z9,1)<=5,pred_GDP_now!L10,"") | M10: =if(rank('Ens_now작업'!M9,'Ens_now작업'!$C9:$Z9,1)<=5,pred_GDP_now!M10,"") | O10: =if(rank('Ens_now작업'!O9,'Ens_now작업'!$C9:$Z9,1)<=5,pred_GDP_now!O10,"") -> 1.1117773 | P10: =if(rank('Ens_now작업'!P9,'Ens_now작업'!$C9:$Z9,1)<=5,pred_GDP_now!P10,"") | Q10: =if(rank('Ens_now작업'!Q9,'Ens_now작업'!$C9:$Z9,1)<=5,pred_GDP_now!Q10,"") -> 0.744322 | AA10: =average(err_GDP_now!AA6:AA9) -> 0.6452605 | AB10: =index($C$1:$AA$1, match(min(C10:AA10),C10:AA10,0)) -> TEXT | AC10: =min(C10:AA10) -> 0.6452605
A11: 201806 | B11: 0.7 | C11: =if(rank('Ens_now작업'!C10,'Ens_now작업'!$C10:$Z10,1)<=5,pred_GDP_now!C11,"") | D11: =if(rank('Ens_now작업'!D10,'Ens_now작업'!$C10:$Z10,1)<=5,pred_GDP_now!D11,"") | E11: =if(rank('Ens_now작업'!E10,'Ens_now작업'!$C10:$Z10,1)<=5,pred_GDP_now!E11,"") | F11: =if(rank('Ens_now작업'!F10,'Ens_now작업'!$C10:$Z10,1)<=5,pred_GDP_now!F11,"") | H11: =if(rank('Ens_now작업'!H10,'Ens_now작업'!$C10:$Z10,1)<=5,pred_GDP_now!H11,"") | I11: =if(rank('Ens_now작업'!I10,'Ens_now작업'!$C10:$Z10,1)<=5,pred_GDP_now!I11,"") | J11: =if(rank('Ens_now작업'!J10,'Ens_now작업'!$C10:$Z10,1)<=5,pred_GDP_now!J11,"") -> 0.54893017 | K11: =if(rank('Ens_now작업'!K10,'Ens_now작업'!$C10:$Z10,1)<=5,pred_GDP_now!K11,"") -> 0.837201 | L11: =if(rank('Ens_now작업'!L10,'Ens_now작업'!$C10:$Z10,1)<=5,pred_GDP_now!L11,"") -> 0.57726227 | M11: =if(rank('Ens_now작업'!M10,'Ens_now작업'!$C10:$Z10,1)<=5,pred_GDP_now!M11,"") | O11: =if(rank('Ens_now작업'!O10,'Ens_now작업'!$C10:$Z10,1)<=5,pred_GDP_now!O11,"") -> 0.4999584 | P11: =if(rank('Ens_now작업'!P10,'Ens_now작업'!$C10:$Z10,1)<=5,pred_GDP_now!P11,"") | Q11: =if(rank('Ens_now작업'!Q10,'Ens_now작업'!$C10:$Z10,1)<=5,pred_GDP_now!Q11,"") -> 0.687899 | AA11: =average(err_GDP_now!AA7:AA10) -> 0.693787 | AB11: =index($C$1:$AA$1, match(min(C11:AA11),C11:AA11,0)) -> RF-DVS | AC11: =min(C11:AA11) -> 0.4999584
A12: 201809 | B12: 0.6 | C12: =if(rank('Ens_now작업'!C11,'Ens_now작업'!$C11:$Z11,1)<=5,pred_GDP_now!C12,"") -> 0.97109739 | D12: =if(rank('Ens_now작업'!D11,'Ens_now작업'!$C11:$Z11,1)<=5,pred_GDP_now!D12,"") | E12: =if(rank('Ens_now작업'!E11,'Ens_now작업'!$C11:$Z11,1)<=5,pred_GDP_now!E12,"") | F12: =if(rank('Ens_now작업'!F11,'Ens_now작업'!$C11:$Z11,1)<=5,pred_GDP_now!F12,"") | H12: =if(rank('Ens_now작업'!H11,'Ens_now작업'!$C11:$Z11,1)<=5,pred_GDP_now!H12,"") | I12: =if(rank('Ens_now작업'!I11,'Ens_now작업'!$C11:$Z11,1)<=5,pred_GDP_now!I12,"") | J12: =if(rank('Ens_now작업'!J11,'Ens_now작업'!$C11:$Z11,1)<=5,pred_GDP_now!J12,"") | K12: =if(rank('Ens_now작업'!K11,'Ens_now작업'!$C11:$Z11,1)<=5,pred_GDP_now!K12,"") -> 0.701816 | L12: =if(rank('Ens_now작업'!L11,'Ens_now작업'!$C11:$Z11,1)<=5,pred_GDP_now!L12,"") -> 0.60425636 | M12: =if(rank('Ens_now작업'!M11,'Ens_now작업'!$C11:$Z11,1)<=5,pred_GDP_now!M12,"") | O12: =if(rank('Ens_now작업'!O11,'Ens_now작업'!$C11:$Z11,1)<=5,pred_GDP_now!O12,"") -> 0.5807563 | P12: =if(rank('Ens_now작업'!P11,'Ens_now작업'!$C11:$Z11,1)<=5,pred_GDP_now!P12,"") | Q12: =if(rank('Ens_now작업'!Q11,'Ens_now작업'!$C11:$Z11,1)<=5,pred_GDP_now!Q12,"") -> 0.679213 | AA12: =average(err_GDP_now!AA8:AA11) -> 0.76204175 | AB12: =index($C$1:$AA$1, match(min(C12:AA12),C12:AA12,0)) -> RF-DVS | AC12: =min(C12:AA12) -> 0.5807563
A13: 201812 | B13: 0.6 | C13: =if(rank('Ens_now작업'!C12,'Ens_now작업'!$C12:$Z12,1)<=5,pred_GDP_now!C13,"") -> 0.26589153 | D13: =if(rank('Ens_now작업'!D12,'Ens_now작업'!$C12:$Z12,1)<=5,pred_GDP_now!D13,"") | E13: =if(rank('Ens_now작업'!E12,'Ens_now작업'!$C12:$Z12,1)<=5,pred_GDP_now!E13,"") | F13: =if(rank('Ens_now작업'!F12,'Ens_now작업'!$C12:$Z12,1)<=5,pred_GDP_now!F13,"") | H13: =if(rank('Ens_now작업'!H12,'Ens_now작업'!$C12:$Z12,1)<=5,pred_GDP_now!H13,"") | I13: =if(rank('Ens_now작업'!I12,'Ens_now작업'!$C12:$Z12,1)<=5,pred_GDP_now!I13,"") | J13: =if(rank('Ens_now작업'!J12,'Ens_now작업'!$C12:$Z12,1)<=5,pred_GDP_now!J13,"") | K13: =if(rank('Ens_now작업'!K12,'Ens_now작업'!$C12:$Z12,1)<=5,pred_GDP_now!K13,"") -> 0.703083 | L13: =if(rank('Ens_now작업'!L12,'Ens_now작업'!$C12:$Z12,1)<=5,pred_GDP_now!L13,"") -> 0.45311828 | M13: =if(rank('Ens_now작업'!M12,'Ens_now작업'!$C12:$Z12,1)<=5,pred_GDP_now!M13,"") | O13: =if(rank('Ens_now작업'!O12,'Ens_now작업'!$C12:$Z12,1)<=5,pred_GDP_now!O13,"") -> 1.1399713 | P13: =if(rank('Ens_now작업'!P12,'Ens_now작업'!$C12:$Z12,1)<=5,pred_GDP_now!P13,"") | Q13: =if(rank('Ens_now작업'!Q12,'Ens_now작업'!$C12:$Z12,1)<=5,pred_GDP_now!Q13,"") -> 0.117679 | AA13: =average(err_GDP_now!AA9:AA12) -> 0.7140075 | AB13: =index($C$1:$AA$1, match(min(C13:AA13),C13:AA13,0)) -> LQR | AC13: =min(C13:AA13) -> 0.117679
A14: 201903 | B14: -0.1 | C14: =if(rank('Ens_now작업'!C13,'Ens_now작업'!$C13:$Z13,1)<=5,pred_GDP_now!C14,"") | D14: =if(rank('Ens_now작업'!D13,'Ens_now작업'!$C13:$Z13,1)<=5,pred_GDP_now!D14,"") | E14: =if(rank('Ens_now작업'!E13,'Ens_now작업'!$C13:$Z13,1)<=5,pred_GDP_now!E14,"") -> -0.32045 | F14: =if(rank('Ens_now작업'!F13,'Ens_now작업'!$C13:$Z13,1)<=5,pred_GDP_now!F14,"") | H14: =if(rank('Ens_now작업'!H13,'Ens_now작업'!$C13:$Z13,1)<=5,pred_GDP_now!H14,"") | I14: =if(rank('Ens_now작업'!I13,'Ens_now작업'!$C13:$Z13,1)<=5,pred_GDP_now!I14,"") | J14: =if(rank('Ens_now작업'!J13,'Ens_now작업'!$C13:$Z13,1)<=5,pred_GDP_now!J14,"") | K14: =if(rank('Ens_now작업'!K13,'Ens_now작업'!$C13:$Z13,1)<=5,pred_GDP_now!K14,"") -> 0.361543 | L14: =if(rank('Ens_now작업'!L13,'Ens_now작업'!$C13:$Z13,1)<=5,pred_GDP_now!L14,"") -> -0.086190051 | M14: =if(rank('Ens_now작업'!M13,'Ens_now작업'!$C13:$Z13,1)<=5,pred_GDP_now!M14,"") | O14: =if(rank('Ens_now작업'!O13,'Ens_now작업'!$C13:$Z13,1)<=5,pred_GDP_now!O14,"") -> 0.61333592 | P14: =if(rank('Ens_now작업'!P13,'Ens_now작업'!$C13:$Z13,1)<=5,pred_GDP_now!P14,"") | Q14: =if(rank('Ens_now작업'!Q13,'Ens_now작업'!$C13:$Z13,1)<=5,pred_GDP_now!Q14,"") -> -0.567977 | AA14: =average(err_GDP_now!AA10:AA13) -> 0.32951275 | AB14: =index($C$1:$AA$1, match(min(C14:AA14),C14:AA14,0)) -> LQR | AC14: =min(C14:AA14) -> -0.567977
